Workbook

Sheet Read me
A1: CNQ – parts to price
A3: What this is
A4: The cost model counts the value of the part on rejections (REJ), rejections with a rework order (REJ_RW), exchanges (EXC) and scraps (SCR) where FTO2 is liable. Today that value is 0 because no price is known.
A5: 132 NCs need a part price. They come down to 91 parts: 60 with a reference written in the NC, 18 with only a FIN, 13 to identify from the NC's wording.
A6: Source: NC exports of 12 Oct 2026 (fto2_dashboard_data_12 and _missing_ids_3), decisions and liability as in the dashboard (NCs created in 2026, every phase).
A8: How the part was found
A9: The reference is read from the NC title and long text (NSA, ABS, ASNA, NAS, EN, E0…, 14-character Airbus articles, 10-digit references). When none is written, the FIN is used; otherwise the part is listed as the NC names it.
A10: The SAP article on the NC is mostly the assembly being built (a VU or a routing), not the rejected part. It is shown in 'NC detail' for reference only.
A11: This is an automatic reading of the texts: check the reference before asking for a price.
A13: What to fill in
A14: Sheet 'Parts to price', yellow cells only: Unit price (€) and Price source. Part value = unit price × quantity.
A15: Sheet 'NC detail' picks the price up by itself. Its 'Part value (€)' column is what the cost model reads as part_value.
... A22: NCs where FTO2 is not liable cost 0 in the model; they are listed in 'Not charged to FTO2' for completeness (112 NCs).

Sheet Parts to price
A1: Part reference / FIN / name | B1: Found as | C1: Part (as named in the NC) | D1: NCs | E1: MSNs | F1: Quantity | G1: Decisions | H1: Products | I1: Lines | J1: First NC | K1: Last NC | L1: NC numbers | M1: Unit price (€) | N1: Price source | O1: Part value (€)
A2: NSA932844CN | B2: Reference in text | C2: SOCLE DE RACCORDEMENT ABIME | D2: 5 | E2: 5 | F2: 5 | G2: REJ_RW 4, REJ 1 | H2: 740VU | I2: A330 | J2: 2026-01-07 | K2: 2026-04-28 | L2: 216060124 216575897 216602069 217107871 217149659 | O2: =IF(M2="","",M2*F2)
A3: MANQUE TROU DE FIXATION ETEC 115VU | B3: To identify | C3: Manque trou de fixation ETEC 115VU | D3: 5 | E3: 5 | F3: 5 | G3: REJ 4, REJ_RW 1 | H3: PTVU | I3: A330 | J3: 2026-07-15 | K3: 2026-09-15 | L3: 217860541 217862026 217895101 217986779 218276828 | O3: =IF(M3="","",M3*F3)
A4: EN3646A02461AN | B4: Reference in text | C4: CONNECTEUR borne ne verrouille pas | D4: 4 | E4: 3 | F4: 4 | G4: REJ 3, REJ_RW 1 | H4: PTVU | I4: A330 | J4: 2026-04-02 | K4: 2026-06-17 | L4: 216915228 216931836 216943435 217584208 | O4: =IF(M4="","",M4*F4)
A5: 6325010000 | B5: Reference in text | C5: DECOUPLING UNIT CASSE | D5: 3 | E5: 3 | F5: 3 | G5: REJ_RW 3 | H5: 740VU | I5: A330 | J5: 2026-01-09 | K5: 2026-04-28 | L5: 216088280 216605359 217149326 | O5: =IF(M5="","",M5*F5)
A6: ABS0064-01 | B6: Reference in text | C6: BOUTON POUSSOIR INCOMPLET | D6: 3 | E6: 2 | F6: 3 | G6: REJ_RW 2, REJ 1 | H6: PTVU | I6: A330 | J6: 2026-04-23 | K6: 2026-04-27 | L6: 217109331 217112253 217139270 | O6: =IF(M6="","",M6*F6)
A7: ABS1424-3-10 | B7: Reference in text | C7: Colonnette de la structure du MIP cassée | D7: 3 | E7: 3 | F7: 3 | G7: EXC 3 | H7: MIP A350, Other | I7: A350 | J7: 2026-03-03 | K7: 2026-07-02 | L7: 216609710 217040142 217749687 | O7: =IF(M7="","",M7*F7)
A8: ABS1650-02 | B8: Reference in text | C8: CABLES ABIMES SUR OPTICAL ENCODER | D8: 3 | E8: 2 | F8: 3 | G8: REJ_RW 3 | H8: PTVU | I8: A330 | J8: 2026-04-07 | K8: 2026-06-19 | L8: 216943511 217613680 217613893 | O8: =IF(M8="","",M8*F8)
A9: ASNA2328-3-4 | B9: Reference in text | C9: Colonnette de la structure du MIP cassée | D9: 3 | E9: 3 | F9: 3 | G9: EXC 3 | H9: Other | I9: A350 | J9: 2026-01-20 | K9: 2026-02-09 | L9: 216177953 216247653 216376660 | O9: =IF(M9="","",M9*F9)
A10: E0062D1S4BA0A | B10: Reference in text | C10: BORNE HS SUR SWITCH OVER | D10: 3 | E10: 3 | F10: 3 | G10: REJ_RW 3 | H10: PTVU | I10: A330 | J10: 2026-06-16 | K10: 2026-09-24 | L10: 217571217 218307795 218376253 | O10: =IF(M10="","",M10*F10)
A11: E0062E2D4AC0A | B11: Reference in text | C11: BORNE NE VERROUILLE PAS | D11: 3 | E11: 1 | F11: 3 | G11: REJ 3 | H11: PTVU | I11: A330 | J11: 2026-01-28 | K11: 2026-03-10 | L11: 216265972 216336723 216669205 | O11: =IF(M11="","",M11*F11)
A12: E0682-01 | B12: Reference in text | C12: Borne 1 HS sur équipement E0682-01 | D12: 3 | E12: 3 | F12: 3 | G12: REJ_RW 2, REJ 1 | H12: PTVU | I12: A330 | J12: 2026-04-15 | K12: 2026-09-24 | L12: 217026822 218227645 218376309 | O12: =IF(M12="","",M12*F12)
A13: 614VU STRUCTURE ENDOMMAGEE | B13: To identify | C13: 614VU STRUCTURE ENDOMMAGEE | D13: 3 | E13: 2 | F13: 3 | G13: REJ_RW 3 | H13: PTVU | I13: A330 | J13: 2026-06-17 | K13: 2026-08-21 | L13: 217590666 218058588 218056243 | O13: =IF(M13="","",M13*F13)
... A92: TUYAUTERIE ATA21 DESSERRÉE | B92: To identify | C92: Tuyauterie ATA21 desserrée | D92: 1 | E92: 1 | F92: 1 | G92: EXC 1 | H92: MIP A350 | I92: A350 | J92: 2026-04-27 | K92: 2026-04-27 | L92: 217147112 | O92: =IF(M92="","",M92*F92)
A94: Total | D94: =SUM(D2:D92) -> 132 | F94: =SUM(F2:F92) -> 132 | M94: =COUNT(M2:M92)&" of "&COUNTA(A2:A92)&" priced" -> 0 of 91 priced | O94: =SUM(O2:O92) -> 0

Sheet NC detail
A1: NC | B1: Decision | C1: Decision label | D1: Phase | E1: Line | F1: Product | G1: MSN | H1: Created | I1: Quantity | J1: Part reference / FIN / name | K1: Part (as named in the NC) | L1: References in text | M1: FIN in text | N1: SAP article of the NC | O1: SAP article description | P1: Unit price (€) | Q1: Part value (€) | R1: NC text (extract)
A2: 217590666 | B2: REJ_RW | C2: Rejection with a rework order | D2: SERIE | E2: A330 | F2: PTVU | G2: 2163 | H2: 2026-06-17 | I2: 1 | J2: 614VU STRUCTURE ENDOMMAGEE | K2: 614VU STRUCTURE ENDOMMAGEE | N2: F9251072200000 | O2: ELEC ASSY 614VU | P2: =IFERROR(IF(INDEX('Parts to price'!$M$2:$M$92,MATCH(J2,'Parts to price'!$A$2:$A$92,0))="","",INDEX('Parts to price'!$M$2:$M$92,MATCH(J2,'Parts to price'!$A$2:$A$92,0))),"") | Q2: =IF(P2="","",P2*I2) | R2: 614VU STRUCTURE ENDOMMAGEE | NonConformity 0001 : Type of nonconformity : Scratch * Sur la ligne A330 , nous constatons que la structure 614VU /MSN 2163/RE058527 a été endommagée ( rayée ) Nous demandons une nouvelle structure pour la refabrication du produit. Text Description : - TEL~ #TEL~ Task Completed : 0200 `` DO00 `` Task Description : NC prise en compte par OF 1030054521. - Task Completed : 0400 `` ATW0 `` Task Description : remis en conformité - Task Completed : 1000 `` ATQ0 `` Task Description : vu remis en conformité
A3: 218058588 | B3: REJ_RW | C3: Rejection with a rework order | D3: SERIE | E3: A330 | F3: PTVU | G3: 2166 | H3: 2026-08-21 | I3: 1 | J3: 614VU STRUCTURE ENDOMMAGEE | K3: 614VU STRUCTURE ENDOMMAGEE | N3: F9251072200000 | O3: ELEC ASSY 614VU | P3: =IFERROR(IF(INDEX('Parts to price'!$M$2:$M$92,MATCH(J3,'Parts to price'!$A$2:$A$92,0))="","",INDEX('Parts to price'!$M$2:$M$92,MATCH(J3,'Parts to price'!$A$2:$A$92,0))),"") | Q3: =IF(P3="","",P3*I3) | R3: 614VU STRUCTURE ENDOMMAGEE | 0000000000 Sur la ligne A330 , nous constatons que la structure 614VU /MSN 2166/RE 059007 a été endommagée ( rayée ) Nous demandons une nouvelle structure pour la refabrication du produit. VOIR STANDARD DOC NonConformity 0001 : Type of nonconformity : Scratch * Sur la ligne A330 , nous constatons que la structure 614VU /MSN 2166/RE 059007 a été endommagée ( rayée ) Nous demandons une nouvelle structure pour la refabrication du produit. VOIR STANDARD DOC Text Description : RAYURE FACE AVANT 614VU - TEL~ #TEL~ Task Completed : 0200 `` DO00 `` Task Description : NC
A4: 218056243 | B4: REJ_RW | C4: Rejection with a rework order | D4: SERIE | E4: A330 | F4: PTVU | G4: 2166 | H4: 2026-08-21 | I4: 1 | J4: 614VU STRUCTURE ENDOMMAGEE | K4: 614VU STRUCTURE ENDOMMAGEE | N4: F9251072200000 | O4: ELEC ASSY 614VU | P4: =IFERROR(IF(INDEX('Parts to price'!$M$2:$M$92,MATCH(J4,'Parts to price'!$A$2:$A$92,0))="","",INDEX('Parts to price'!$M$2:$M$92,MATCH(J4,'Parts to price'!$A$2:$A$92,0))),"") | Q4: =IF(P4="","",P4*I4) | R4: 614VU STRUCTURE ENDOMMAGEE | 0000000000 Sur la ligne A330 , nous constatons que la structure 614VU /MSN 2166/RE059006 a été endommagée ( rayée ) Nous demandons une nouvelle structure pour la refabrication du produit. VOIR STANDARD DOC NonConformity 0001 : Type of nonconformity : Scratch * Sur la ligne A330 , nous constatons que la structure 614VU /MSN 2166/RE059006 a été endommagée ( rayée ) Nous demandons une nouvelle structure pour la refabrication du produit. VOIR STANDARD DOC Text Description : rayure sur la face avant du 614 VU - TEL~ #TEL~ Task Completed : 0200 `` DO00 `` Task Descript
A5: 216088280 | B5: REJ_RW | C5: Rejection with a rework order | D5: SERIE | E5: A330 | F5: 740VU | G5: 2143 | H5: 2026-01-09 | I5: 1 | J5: 6325010000 | K5: VIS ET FILETAGE SUR DECOUPLING UNIT H.S. | L5: 6325010000 | N5: F92511185000S23 | O5: FINITION 740VU | P5: =IFERROR(IF(INDEX('Parts to price'!$M$2:$M$92,MATCH(J5,'Parts to price'!$A$2:$A$92,0))="","",INDEX('Parts to price'!$M$2:$M$92,MATCH(J5,'Parts to price'!$A$2:$A$92,0))),"") | Q5: =IF(P5="","",P5*I5) | R5: VIS ET FILETAGE SUR DECOUPLING UNIT H.S. | NonConformity 0001 : Type of nonconformity : Electrical Assembly Installation * Lors du contrôle final du 740VU , MSN 2143 , nous constatons que le Decoupling Unit réf. 6325010000 est endommagé. La vis et le filetage sont H.S. * Nous demandons le remplacement de la pièce. Task Completed : 0100 `` DEC0 `` Decision Taken : REJECT Part Fitted Justification : EQUIPEMENT ENDOMMAGE * MRP CONTROLER : #PRS~ #PRS~ #UID~ MATERIAL GROUP : ++++++++++++++++++++++++++++++++++++++++ * Text Description : - Task Completed : 0150 `` DO00 `` Task Description : NC PRIS
A6: 216605359 | B6: REJ_RW | C6: Rejection with a rework order | D6: SERIE | E6: A330 | F6: 740VU | G6: 2152 | H6: 2026-03-03 | I6: 1 | J6: 6325010000 | K6: Vis de fixation endommagée decoupling | L6: 6325010000 | M6: 17CE | P6: =IFERROR(IF(INDEX('Parts to price'!$M$2:$M$92,MATCH(J6,'Parts to price'!$A$2:$A$92,0))="","",INDEX('Parts to price'!$M$2:$M$92,MATCH(J6,'Parts to price'!$A$2:$A$92,0))),"") | Q6: =IF(P6="","",P6*I6) | R6: Vis de fixation endommagée decoupling | TEL~ #TEL~ NonConformity 0001 : Type of nonconformity : Electrical Assembly Installation * Lors de l'installation du decoupling unit pwr FIN 17CE ; P/N:530AL01CN S/N : 66874 CMS:6325010000 sur le socle de la platine relais du 740VU MSN 2152 nous avons constaté que la vis de fixation de celui-ci est endommagée . * Merci de nous fournir un nouvel equipement TEL~ #TEL~ Task Completed : 0100 `` DEC0 `` Decision Taken : REJECT Part Fitted Justification : vis de fixations endommagée ++++++++++++++++++++++++++++++++++++++++ Material characteristics * WBS : MSF
A7: 217149326 | B7: REJ_RW | C7: Rejection with a rework order | D7: SERIE | E7: A330 | F7: 740VU | G7: 2154 | H7: 2026-04-28 | I7: 1 | J7: 6325010000 | K7: DECOUPLING UNIT CASSE | L7: 6325010000 | M7: 17CE | N7: F92511185000S23 | O7: FINITION 740VU | P7: =IFERROR(IF(INDEX('Parts to price'!$M$2:$M$92,MATCH(J7,'Parts to price'!$A$2:$A$92,0))="","",INDEX('Parts to price'!$M$2:$M$92,MATCH(J7,'Parts to price'!$A$2:$A$92,0))),"") | Q7: =IF(P7="","",P7*I7) | R7: DECOUPLING UNIT CASSE | NonConformity 0001 : Type of nonconformity : Electrical Assembly Installation * Sur la ligne A330 , 740VU , MSN 2154 , nous constatons que le decoupling unit 6325010000 sur FIN 17CE est cassé. * Nous demandons le remplacement de l'équipement Text Description : - TEL~ #TEL~ Task Completed : 0200 `` DO00 `` Task Description : NC prise en compte par OF 1029395238 .
A8: 216364146 | B8: REJ | C8: Rejection | D8: SERIE | E8: A330 | F8: 743VU | G8: 2149 | H8: 2026-02-06 | I8: 1 | J8: 6325011700 | K8: MANQUE ECROU SUR BASE CONTACTEUR | L8: 6325011700 | N8: F92513900000S02 | O8: MECA MEUBLE 743VU | P8: =IFERROR(IF(INDEX('Parts to price'!$M$2:$M$92,MATCH(J8,'Parts to price'!$A$2:$A$92,0))="","",INDEX('Parts to price'!$M$2:$M$92,MATCH(J8,'Parts to price'!$A$2:$A$92,0))),"") | Q8: =IF(P8="","",P8*I8) | R8: MANQUE ECROU SUR BASE CONTACTEUR | NonConformity 0001 : Type of nonconformity : Electrical Assembly Installation * Sur la ligne A330 , MSN 2149 , 743 VU , nous constatons lors de l'installation que l'écrou en borne F est manquant sur le base contacteur 6325011700. * Nous demandons le remplacement de l'équipement. Text Description : - TEL~ #TEL~ Task Completed : 0200 `` DO00 `` Task Description : Pas d'action côté ST - TEL~ Task Completed : 0400 `` ATW0 `` Task Description : Travail effectué - Task Completed : 1000 `` ATQ0 `` Task Description : REMIS EN CONFORMITE
A9: 218048183 | B9: REJ_RW | C9: Rejection with a rework order | D9: SERIE | E9: A330 | F9: Other | G9: 2136 | H9: 2026-08-20 | I9: 1 | J9: 6325018500 | K9: VU/BUTTON/MECA | L9: 6325018500 | M9: 2WD1 | N9: FREW25CABINMUL018A | O9: VERIF. INSPEC. ASSIST. FINAL CABINE | P9: =IFERROR(IF(INDEX('Parts to price'!$M$2:$M$92,MATCH(J9,'Parts to price'!$A$2:$A$92,0))="","",INDEX('Parts to price'!$M$2:$M$92,MATCH(J9,'Parts to price'!$A$2:$A$92,0))),"") | Q9: =IF(P9="","",P9*I9) | R9: VU/BUTTON/MECA | Non Conformity 0001 : Type of nonconformity : Part incorrectly fitted * Suite QSR COCKPIT / Cockpit / Aircraft axe / VU BUTTON / - AAD - Pièce mal montée / positionnée Suite au QSR TO/F/EQ/26-00012 nous demandons le remplacement de l'équipement 2WD1 faisant partie du 255VU. * P/N : 334VZ01Y00 CMS : 6325018500 S/N : 334VZ40588 * Demandons intervention. Code cause : Défectueux / endommagé cassé NC_W Due to QSR COCKPIT / Cockpit / Aircraft axe / VU BUTTON / - AAD - Part incorrectly fitted Following QSR TO/F/EQ/26-00012 we require the replacement of equipment 2WD1 which is part
A10: 216701404 | B10: REJ_RW | C10: Rejection with a rework order | D10: SERIE | E10: A330 | F10: PTVU | G10: 2151 | H10: 2026-03-12 | I10: 1 | J10: 6330420000 | K10: ERGOT WARNING HORN H.S. | L10: 6330420000 | N10: F9251685600000 | O10: ELEC ASSY 265VU | P10: =IFERROR(IF(INDEX('Parts to price'!$M$2:$M$92,MATCH(J10,'Parts to price'!$A$2:$A$92,0))="","",INDEX('Parts to price'!$M$2:$M$92,MATCH(J10,'Parts to price'!$A$2:$A$92,0))),"") | Q10: =IF(P10="","",P10*I10) | R10: ERGOT WARNING HORN H.S. | NonConformity 0001 : Type of nonconformity : Electrical Assembly Installation * Sur la ligne A330 , MSN 2151 , 265VU , nous constatons lors de l'installation que l'ergot sur le warning horn 6330420000 est endomagé. * Nous demandons le remplacement de l'équipement. Text Description : - TEL~ #TEL~ Task Completed : 0150 `` DO00 `` Task Description : NC taité sur S03 1028810052 - TEL~ Task Completed : 0400 `` ATW0 `` Task Description : Travail effectué - Task Completed : 1000 `` ATQ0 `` Task Description : Check ok
A11: 17063910 | B11: REJ | C11: Rejection | D11: SERIE | E11: A330 | F11: Other | G11: 2151 | H11: 2026-03-12 | I11: 1 | J11: 6330420000 | K11: ERGOT WARNING HORN H.S. | L11: 6330420000 | P11: =IFERROR(IF(INDEX('Parts to price'!$M$2:$M$92,MATCH(J11,'Parts to price'!$A$2:$A$92,0))="","",INDEX('Parts to price'!$M$2:$M$92,MATCH(J11,'Parts to price'!$A$2:$A$92,0))),"") | Q11: =IF(P11="","",P11*I11) | R11: ERGOT WARNING HORN H.S. | NonConformity 0001 : Type of nonconformity : Electrical Assembly Installation * Sur la ligne A330 , MSN 2151 , 265VU , nous constatons lors de l'installation que l'ergot sur le warning horn 6330420000 est endomagé. * Nous demandons le remplacement de l'équipement.
A12: 217344532 | B12: REJ | C12: Rejection | D12: SERIE | E12: A330 | F12: PTVU | G12: 2159 | H12: 2026-05-21 | I12: 1 | J12: 6374843100 | K12: ETEC 417LF NON CONFORME | L12: 6374843100 | M12: 417LF | N12: F9251671100000 | O12: ELEC ASSY 417VU | P12: =IFERROR(IF(INDEX('Parts to price'!$M$2:$M$92,MATCH(J12,'Parts to price'!$A$2:$A$92,0))="","",INDEX('Parts to price'!$M$2:$M$92,MATCH(J12,'Parts to price'!$A$2:$A$92,0))),"") | Q12: =IF(P12="","",P12*I12) | R12: ETEC 417LF NON CONFORME | NonConformity 0001 : Type of nonconformity : Harness * DEF 1-Q11 : ETEC 417LF CMS 6374843100 SURPLUS DE MATIERE POUR LE MONTAGE CORRECTE D'UNE VIS. Text Description : - Task Completed : 0150 `` DO00 `` Task Description : nc prise en compte par so3 1029282330 - TEL~ #TEL~ Task Completed : 0200 `` DO00 `` Task Description : Pas d'action côté ST / suivre OF série pour la suite des OP. - TEL~ Task Completed : 0400 `` ATW0 `` Task Description : TRAVAIL EFFECTUE - Task Completed : 1000 `` ATQ0 `` Task Description : remis en conformité
A13: 216064934 | B13: REJ_RW | C13: Rejection with a rework order | D13: REC | E13: A330 | F13: 414VU | G13: 2139 | H13: 2026-01-07 | I13: 1 | J13: 6374865800 | K13: INTEGRALLY LIGHTED PLATE HS | L13: 6374865800 | P13: =IFERROR(IF(INDEX('Parts to price'!$M$2:$M$92,MATCH(J13,'Parts to price'!$A$2:$A$92,0))="","",INDEX('Parts to price'!$M$2:$M$92,MATCH(J13,'Parts to price'!$A$2:$A$92,0))),"") | Q13: =IF(P13="","",P13*I13) | R13: INTEGRALLY LIGHTED PLATE HS | NonConformity 0001 : Type of nonconformity : Electrical Assembly Installation * Suite à NC 216057897 , création de la NC pour remplacement de la INTEGRALLY LIGHTED PLATE 6374865800. la remise en conformité sera faite par l'équipe REC. * Task Completed : 0100 `` DEC0 `` Decision Taken : REJECT Part Fitted Justification : INTEGRALLY LIGHTED PLATE HS ++++++++++++++++++++++++++++++++++++++++ Material characteristics * WBS : MSF-002139/FB164 Material : 000000006374865800 * MRP CONTROLER : SMITH Emmanuel STORAGE LOCATION : TS2F MATERIAL GROUP : BLAF LIGHTED_PLATE +++++
A14: 216704810 | B14: REJ | C14: Rejection | D14: SERIE | E14: A330 | F14: PTVU | G14: 2158 | H14: 2026-03-12 | I14: 1 | J14: 6374867600 | K14: INTEGRALLY LIGHTED PLATE H.S. | L14: 6374867600 | N14: F9251649700000 | O14: ELEC ASSY 245VU | P14: =IFERROR(IF(INDEX('Parts to price'!$M$2:$M$92,MATCH(J14,'Parts to price'!$A$2:$A$92,0))="","",INDEX('Parts to price'!$M$2:$M$92,MATCH(J14,'Parts to price'!$A$2:$A$92,0))),"") | Q14: =IF(P14="","",P14*I14) | R14: INTEGRALLY LIGHTED PLATE H.S. | NonConformity 0001 : Type of nonconformity : Electrical Assembly Installation * Sur la ligne A330 , MSN 2158 , 245VU , nous constatons lors de la réception que la lighted plate 6374867600 est endommagée. Voir standard doc. * Nous demandons le remplacement de l'équipement. Task Completed : 0100 `` DEC0 `` Decision Taken : REJECT Part Not Fitted Justification : Etec rayée ++++++++++++++++++++++++++++++++++++++++ Material characteristics * WBS : MSF-002158/FB149 Material : 000000006374867600 * MRP CONTROLER : SMITH Emmanuel STORAGE LOCATION : TS2F MATERIAL GROUP :
A15: 217109331 | B15: REJ_RW | C15: Rejection with a rework order | D15: SERIE | E15: A330 | F15: PTVU | G15: 2155 | H15: 2026-04-23 | I15: 1 | J15: ABS0064-01 | K15: BOUTON POUSSOIR INCOMPLET | L15: ABS0064-01 | N15: F9251694600000 | O15: ELEC ASSY 261VU | P15: =IFERROR(IF(INDEX('Parts to price'!$M$2:$M$92,MATCH(J15,'Parts to price'!$A$2:$A$92,0))="","",INDEX('Parts to price'!$M$2:$M$92,MATCH(J15,'Parts to price'!$A$2:$A$92,0))),"") | Q15: =IF(P15="","",P15*I15) | R15: BOUTON POUSSOIR INCOMPLET | NonConformity 0001 : Type of nonconformity : Electrical Assembly Installation * Sur la ligne A330 , MSN 2155 , 261VU , nous constatons que le bouton poussoir ABS0064-01 est incomplet. Rondelle et écrou manquants. * Nous demandons le remplacement de l'équipement. Text Description : - TEL~ #TEL~ Task Completed : 0200 `` DO00 `` Task Description : 1029379066 TEL~ #TEL~ NC prise en compte par OF 1029379066. - TEL~ Task Completed : 0400 `` ATW0 `` Task Description : Travail effectué - Task Completed : 1000 `` ATQ0 `` Task Description : CHECK OK *
A16: 217112253 | B16: REJ_RW | C16: Rejection with a rework order | D16: SERIE | E16: A330 | F16: PTVU | G16: 2155 | H16: 2026-04-23 | I16: 1 | J16: ABS0064-01 | K16: BOUTON POUSSOIR INCOMPLET | L16: ABS0064-01 | M16: 14WH | N16: F9251695700000 | O16: ELEC ASSY 262VU | P16: =IFERROR(IF(INDEX('Parts to price'!$M$2:$M$92,MATCH(J16,'Parts to price'!$A$2:$A$92,0))="","",INDEX('Parts to price'!$M$2:$M$92,MATCH(J16,'Parts to price'!$A$2:$A$92,0))),"") | Q16: =IF(P16="","",P16*I16) | R16: BOUTON POUSSOIR INCOMPLET | NonConformity 0001 : Type of nonconformity : Electrical Assembly Installation * Sur la ligne A330 , MSN 2155 , 262VU , nous constatons que le bouton poussoir ABS0064-01 est incomplet : Rondelle et écrou manquants. * Nous demandons le remplacement de l'équipement. * Text Description : TEL~ #TEL~ Concerné FIN 14WH - TEL~ #TEL~ Task Completed : 0200 `` DO00 `` Task Description : NC prise en compte par OF 1029378973. - TEL~ Task Completed : 0400 `` ATW0 `` Task Description : travail effectué - Task Completed : 1000 `` ATQ0 `` Task Description : CHECK OK
A17: 217139270 | B17: REJ | C17: Rejection | D17: SERIE | E17: A330 | F17: PTVU | G17: 2140 | H17: 2026-04-27 | I17: 1 | J17: ABS0064-01 | K17: BOUTON POUSSOIR ENDOMMAGE | L17: ABS0064-01 | N17: F9251693200000 | O17: ELEC ASSY 261VU | P17: =IFERROR(IF(INDEX('Parts to price'!$M$2:$M$92,MATCH(J17,'Parts to price'!$A$2:$A$92,0))="","",INDEX('Parts to price'!$M$2:$M$92,MATCH(J17,'Parts to price'!$A$2:$A$92,0))),"") | Q17: =IF(P17="","",P17*I17) | R17: BOUTON POUSSOIR ENDOMMAGE | NonConformity 0001 : Type of nonconformity : Electrical Assembly Installation * Sur la ligne A330 , nous avons constaté que le bouton poussoir ABS0064-01 est endommagé. * Text Description : - TEL~ Task Completed : 0400 `` ATW0 `` Task Description : Travail effectué - Task Completed : 1000 `` ATQ0 `` Task Description : remis en conformité
A18: 216758007 | B18: REJ | C18: Rejection | D18: SERIE | E18: A330 | F18: PTVU | G18: 2158 | H18: 2026-03-18 | I18: 1 | J18: ABS0951B3LM002 | K18: INDICATEUR ABS0951B3LM002 H.S. | L18: ABS0951B3LM002 | N18: F9251649300000 | O18: ELEC ASSY 221VU | P18: =IFERROR(IF(INDEX('Parts to price'!$M$2:$M$92,MATCH(J18,'Parts to price'!$A$2:$A$92,0))="","",INDEX('Parts to price'!$M$2:$M$92,MATCH(J18,'Parts to price'!$A$2:$A$92,0))),"") | Q18: =IF(P18="","",P18*I18) | R18: INDICATEUR ABS0951B3LM002 H.S. | NonConformity 0001 : Type of nonconformity : Electrical Assembly Installation * Sur la ligne A330 , MSN 2158 , 221VU , nous constatons lors de l'installation que l'indicateur ABS0951B3LM002 est endommagé. * Nous demandons le remplacement de l'équipement. Text Description : TEL~ #TEL~ Pas d'action côté ST - Task Completed : 1000 `` ATQ0 `` Task Description : Check ok
A19: 217253448 | B19: REJ_RW | C19: Rejection with a rework order | D19: SERIE | E19: A330 | F19: PTVU | G19: 2159 | H19: 2026-05-11 | I19: 1 | J19: ABS0951B3LP114 | K19: INDICATEUR ENDOMMAGE | L19: ABS0951B3LP114 | M19: 27MQ | N19: F9251684300000 | O19: ELEC ASSY 271VU | P19: =IFERROR(IF(INDEX('Parts to price'!$M$2:$M$92,MATCH(J19,'Parts to price'!$A$2:$A$92,0))="","",INDEX('Parts to price'!$M$2:$M$92,MATCH(J19,'Parts to price'!$A$2:$A$92,0))),"") | Q19: =IF(P19="","",P19*I19) | R19: INDICATEUR ENDOMMAGE | NonConformity 0001 : Type of nonconformity : Electrical Assembly Installation * Sur la ligne A330 , MSN 2159 , 271 VU , nous constatons que l'indicateur ABS0951B3LP114 sur le FIN 27MQ est endommagé. * Nous demandons le remplacement de l'équipement. Text Description : - TEL~ #TEL~ Task Completed : 0200 `` DO00 `` Task Description : NCprise en compte par OF 1029590952. - TEL~ Task Completed : 0400 `` ATW0 `` Task Description : travail effectué - Task Completed : 1000 `` ATQ0 `` Task Description : Vu remis en conformité
A20: 217447449 | B20: REJ | C20: Rejection | D20: SERIE | E20: A330 | F20: PTVU | G20: 2161 | H20: 2026-06-03 | I20: 1 | J20: ABS0971-003A01 | K20: CABLE COURT SUITE ERREUR SERTISSAGE | L20: ABS0971-003A01 | N20: F9251689100000 | O20: ELEC ASSY 538VU | P20: =IFERROR(IF(INDEX('Parts to price'!$M$2:$M$92,MATCH(J20,'Parts to price'!$A$2:$A$92,0))="","",INDEX('Parts to price'!$M$2:$M$92,MATCH(J20,'Parts to price'!$A$2:$A$92,0))),"") | Q20: =IF(P20="","",P20*I20) | R20: CABLE COURT SUITE ERREUR SERTISSAGE | NonConformity 0001 : Type of nonconformity : Electrical Assembly Installation * Sur la ligne A330 , MSN 2161 , 538VU , nous constatons suite à une erreur de sertissage que le câble 4631-1221 est trop court. * Nous demandons la re fabrication du câble ainsi que l'installation du connecteur ABS0971-003A01. Task Completed : 0100 `` DEC0 `` Decision Taken : REJECT Part Not Fitted Justification : Câble 4631-1221 trop court suite à erreur de sertissage * MRP CONTROLER : MATERIAL GROUP : ++++++++++++++++++++++++++++++++++++++++ * Text Description : - Task Compl
A21: 216609710 | B21: EXC | C21: Exchange | D21: SERIE | E21: A350 | F21: MIP A350 | G21: 829 | H21: 2026-03-03 | I21: 1 | J21: ABS1424-3-10 | K21: Colonnette de la structure du MIP cassée | L21: ABS1424-3-10 | N21: V92814615000S01 | O21: Intégration harnais 1101VB sur MIP | P21: =IFERROR(IF(INDEX('Parts to price'!$M$2:$M$92,MATCH(J21,'Parts to price'!$A$2:$A$92,0))="","",INDEX('Parts to price'!$M$2:$M$92,MATCH(J21,'Parts to price'!$A$2:$A$92,0))),"") | Q21: =IF(P21="","",P21*I21) | R21: Colonnette de la structure du MIP cassée | TEL~ #TEL~ NonConformity 0001 : Type of nonconformity : Structural and Mechanical Assembly * Sur le MIP A350 poste integration nous avons endommagé la colonette ABS 1424-3-10 situé dans le pylone central. Veuillez s'il vous plait proceder à sont remplacement. TEL~ #TEL~ Task Completed : 0100 `` DEC0 `` Request for Supplier Assessment Decision Taken : External Exchange Text Description : - Task Completed : 1000 `` ATQ0 `` Task Description : Travail effectué par CIB. - Task Completed : 1000 `` ATQ0 `` Task Description : > X > X* Task Description : >
A22: 217040142 | B22: EXC | C22: Exchange | D22: SERIE | E22: A350 | F22: Other | G22: 843 | H22: 2026-04-16 | I22: 1 | J22: ABS1424-3-10 | K22: Colonnette de la structure du MIP cassée | L22: ABS1424-3-10 | P22: =IFERROR(IF(INDEX('Parts to price'!$M$2:$M$92,MATCH(J22,'Parts to price'!$A$2:$A$92,0))="","",INDEX('Parts to price'!$M$2:$M$92,MATCH(J22,'Parts to price'!$A$2:$A$92,0))),"") | Q22: =IF(P22="","",P22*I22) | R22: Colonnette de la structure du MIP cassée | NonConformity 0001 : Type of nonconformity : Broken * Sur le MIP A350 , MSN843 , un opérateur nous a signalé qu’il a endommagé une colonnette de référence ABS1424-3-10 dans le pylône. Aprés constatation nous demandons le remplacement de celle-ci. Task Completed : 0100 `` DEC0 `` Request for Supplier Assessment Decision Taken : External Exchange Text Description :
A23: 217749687 | B23: EXC | C23: Exchange | D23: SERIE | E23: A350 | F23: MIP A350 | G23: 860 | H23: 2026-07-02 | I23: 1 | J23: ABS1424-3-10 | K23: Colonette Cassée | L23: ABS1424-3-10 | N23: V92814615000S01 | O23: Intégration harnais 1101VB sur MIP | P23: =IFERROR(IF(INDEX('Parts to price'!$M$2:$M$92,MATCH(J23,'Parts to price'!$A$2:$A$92,0))="","",INDEX('Parts to price'!$M$2:$M$92,MATCH(J23,'Parts to price'!$A$2:$A$92,0))),"") | Q23: =IF(P23="","",P23*I23) | R23: Colonette Cassée | 567198748 NonConformity 0001 : Type of nonconformity : Structural and Mechanical Assembly * Sur le MIP A350 poste integration npous avons endommagé la colonette ABS 1424-3-10 situé dans le pylone central. Veuillez s'il vous plait proceder à sont remplacement NonConformity 0001 : Type of nonconformity : Structural and Mechanical Assembly * Sur le MIP A350 poste integration nous avons endommagé la colonette ABS 1424-3-10 situé dans le pylone central. Veuillez s'il vous plait proceder à sont remplacement TEL~ #TEL~ Task Completed : 0100 `` DEC0 `` Request for Supplier Assessm
A24: 216846510 | B24: REJ | C24: Rejection | D24: SERIE | E24: A330 | F24: PTVU | G24: 2153 | H24: 2026-03-26 | I24: 1 | J24: ABS1551L4AD0A | K24: EQUIPEMENT ENDOMMAGE | L24: ABS1551L4AD0A | N24: F9251672000000 | O24: ELEC ASSY 119VU | P24: =IFERROR(IF(INDEX('Parts to price'!$M$2:$M$92,MATCH(J24,'Parts to price'!$A$2:$A$92,0))="","",INDEX('Parts to price'!$M$2:$M$92,MATCH(J24,'Parts to price'!$A$2:$A$92,0))),"") | Q24: =IF(P24="","",P24*I24) | R24: EQUIPEMENT ENDOMMAGE | NonConformity 0001 : Type of nonconformity : Electrical Assembly Installation * Sur la ligne A330 , MSN 2153 , 119VU , nous constatons que l'équipement ABS1551L4AD0A est endommagé. * Nous demandons le remplcement de l'équipement. Text Description : - TEL~ #TEL~ Task Completed : 0150 `` DO00 `` Task Description : > X TEL~ #TEL~ > X* NC traité sur SO1 * - TEL~ #TEL~ Task Completed : 0200 `` DO00 `` Task Description : > X TEL~ #TEL~ > X* Pas d'action côté ST. * - TEL~ Task Completed : 0400 `` ATW0 `` Task Description : Travail effectué
A25: 216943511 | B25: REJ_RW | C25: Rejection with a rework order | D25: SERIE | E25: A330 | F25: PTVU | G25: 2158 | H25: 2026-04-07 | I25: 1 | J25: ABS1650-02 | K25: BOUTON OPTICAL ENCODEUR HS | L25: ABS1650-02 | N25: F9251647200000 | O25: ELEC ASSY 313VU | P25: =IFERROR(IF(INDEX('Parts to price'!$M$2:$M$92,MATCH(J25,'Parts to price'!$A$2:$A$92,0))="","",INDEX('Parts to price'!$M$2:$M$92,MATCH(J25,'Parts to price'!$A$2:$A$92,0))),"") | Q25: =IF(P25="","",P25*I25) | R25: BOUTON OPTICAL ENCODEUR HS | NonConformity 0001 : Type of nonconformity : Electrical Assembly Installation * Sur la ligne A330 , nous constatons que le bouton de l'encodeur optical est endommagé = > ABS1650-02. nous demandons la remise en conformité du produit. Text Description : - TEL~ #TEL~ Task Completed : 0150 `` DO00 `` Task Description : NC traitée sous SO3 1029127030 - TEL~ #TEL~ Task Completed : 0200 `` DO00 `` Task Description : Pas d'action côté ST - TEL~ Task Completed : 0400 `` ATW0 `` Task Description : Travail effectué
A26: 217613680 | B26: REJ_RW | C26: Rejection with a rework order | D26: SERIE | E26: A330 | F26: PTVU | G26: 2163 | H26: 2026-06-19 | I26: 1 | J26: ABS1650-02 | K26: CABLES ABIMES SUR OPTICAL ENCODER | L26: ABS1650-02 | N26: F9251647200000 | O26: ELEC ASSY 313VU | P26: =IFERROR(IF(INDEX('Parts to price'!$M$2:$M$92,MATCH(J26,'Parts to price'!$A$2:$A$92,0))="","",INDEX('Parts to price'!$M$2:$M$92,MATCH(J26,'Parts to price'!$A$2:$A$92,0))),"") | Q26: =IF(P26="","",P26*I26) | R26: CABLES ABIMES SUR OPTICAL ENCODER | NonConformity 0001 : Type of nonconformity : Electrical Assembly Installation * Sur la ligne A330 , MSN 2163 , 313 VU , nous constatons que les câbles sur l'optical encoder ABS1650-02 ont été abîmés par la pince à dénuder. * Nous demandons le remplacement de l'équipement. Text Description : - TEL~ #TEL~ Task Completed : 0200 `` DO00 `` Task Description : NC prise en compte per OF 1030084727. - Task Completed : 0400 `` ATW0 `` Task Description : remis en conformité - Task Completed : 1000 `` ATQ0 `` Task Description : CHECK OK
A27: 217613893 | B27: REJ_RW | C27: Rejection with a rework order | D27: SERIE | E27: A330 | F27: PTVU | G27: 2163 | H27: 2026-06-19 | I27: 1 | J27: ABS1650-02 | K27: CABLES ABIMES SUR OPTICAL ENCODER | L27: ABS1650-02 | N27: F9251647400000 | O27: ELEC ASSY 314VU | P27: =IFERROR(IF(INDEX('Parts to price'!$M$2:$M$92,MATCH(J27,'Parts to price'!$A$2:$A$92,0))="","",INDEX('Parts to price'!$M$2:$M$92,MATCH(J27,'Parts to price'!$A$2:$A$92,0))),"") | Q27: =IF(P27="","",P27*I27) | R27: CABLES ABIMES SUR OPTICAL ENCODER | NonConformity 0001 : Type of nonconformity : Electrical Assembly Installation * Sur la ligne A330 , MSN 2163 , 314 VU , nous constatons que les câbles sur l'optical encoder ABS1650-02 sont abîmés suite à un mauvais dénudage. * Nous demandons le remplacement de l'équipement. Text Description : - TEL~ #TEL~ Task Completed : 0200 `` DO00 `` Task Description : NC prise en compte par OF 1030085567 - Task Completed : 0400 `` ATW0 `` Task Description : remis en conformité - Task Completed : 1000 `` ATQ0 `` Task Description : CHECK OK *
A28: 216958097 | B28: REJ | C28: Rejection | D28: SERIE | E28: A330 | F28: PTVU | G28: 2158 | H28: 2026-04-08 | I28: 1 | J28: ABS1650-03 | K28: BOUTON OPTICAL ENCODEUR HS | L28: ABS1650-03 | N28: F9251647200000 | O28: ELEC ASSY 313VU | P28: =IFERROR(IF(INDEX('Parts to price'!$M$2:$M$92,MATCH(J28,'Parts to price'!$A$2:$A$92,0))="","",INDEX('Parts to price'!$M$2:$M$92,MATCH(J28,'Parts to price'!$A$2:$A$92,0))),"") | Q28: =IF(P28="","",P28*I28) | R28: BOUTON OPTICAL ENCODEUR HS | NonConformity 0001 : Type of nonconformity : Electrical Assembly Installation * Sur la ligne A330 , nous constatons que le bouton de l'encodeur optical a été endommagé. ABS1650-03 Task Completed : 0100 `` DEC0 `` Decision Taken : REJECT Part Not Fitted Justification : BOUTON ENDOMMAGE * MRP CONTROLER : MATERIAL GROUP : ++++++++++++++++++++++++++++++++++++++++ * Text Description : - TEL~ #TEL~ Task Completed : 0150 `` DO00 `` Task Description : traitée sous 1028548452 - Task Completed : 1000 `` ATQ0 `` Task Description : produit remis en conformité
A29: 218388588 | B29: REJ_RW | C29: Rejection with a rework order | D29: SERIE | E29: A330 | F29: PTVU | G29: 2170 | H29: 2026-09-24 | I29: 1 | J29: ABS1650-03 | K29: Optical encoder endommagé | L29: ABS1650-03 | M29: 105SG1 | N29: F9251647200000 | O29: ELEC ASSY 313VU | P29: =IFERROR(IF(INDEX('Parts to price'!$M$2:$M$92,MATCH(J29,'Parts to price'!$A$2:$A$92,0))="","",INDEX('Parts to price'!$M$2:$M$92,MATCH(J29,'Parts to price'!$A$2:$A$92,0))),"") | Q29: =IF(P29="","",P29*I29) | R29: Optical encoder endommagé | NonConformity 0001 : Type of nonconformity : Electrical Assembly Installation * Sur la ligne A330 , 313VU , nous constatons que le optical encoder ABS1650-03 sur le FIN 105SG1 est endommagé Text Description : - TEL~ #TEL~ Task Completed : 0200 `` DO00 `` Task Description : NC prise en compte par OF 1031192907 .
A30: 217921499 | B30: REJ_RW | C30: Rejection with a rework order | D30: SERIE | E30: A350 | F30: MIP A350 | G30: 866 | H30: 2026-07-22 | I30: 1 | J30: ABS1896A08E | K30: Backshell abimé lors du torquage | L30: ABS1896A08E | M30: 52CV-A | N30: VESAW92C31101TA2M | O30: 1101VB MIP SUPER 2M A | P30: =IFERROR(IF(INDEX('Parts to price'!$M$2:$M$92,MATCH(J30,'Parts to price'!$A$2:$A$92,0))="","",INDEX('Parts to price'!$M$2:$M$92,MATCH(J30,'Parts to price'!$A$2:$A$92,0))),"") | Q30: =IF(P30="","",P30*I30) | R30: Backshell abimé lors du torquage | NonConformity 0001 : Type of nonconformity : Mis-alignment * Sur la route 2M du MSN 866 , le backshell ABS1896A08E de la prise 52CV-A s'est abimé lors du torquage. ( détrompeur HS ) Merci de nous en fournir un nouveau Text Description : - Task Completed : 0400 `` ATW0 `` Task Description : NC OK - Task Completed : 1000 `` ATQ0 `` Task Description : E/S backshell effectué
A31: 216758388 | B31: EXC | C31: Exchange | D31: SERIE | E31: A350 | F31: Other | G31: 835 | H31: 2026-03-18 | I31: 1 | J31: ASNA2327-3-3 | K31: Ecrou riveté endommagé sur la structure | L31: ASNA2327-3-3 | P31: =IFERROR(IF(INDEX('Parts to price'!$M$2:$M$92,MATCH(J31,'Parts to price'!$A$2:$A$92,0))="","",INDEX('Parts to price'!$M$2:$M$92,MATCH(J31,'Parts to price'!$A$2:$A$92,0))),"") | Q31: =IF(P31="","",P31*I31) | R31: Ecrou riveté endommagé sur la structure | NonConformity 0001 : Type of nonconformity : Fastener ( incl. Bolt/Screw/Washer/Bush ) * Sur la ligne A350 , poste Integration , nous avons constaté que l'écrou riveté ASNA2327-3-3 est endommagé . Nous demmandons une intervention pour la remise en conformité de la structure. Task Completed : 0100 `` DEC0 `` Request for Supplier Assessment Decision Taken : External Exchange Text Description : - Task Completed : 1000 `` ATQ0 `` Task Description : Travail effectué par CIB .
A32: 218277387 | B32: EXC | C32: Exchange | D32: SERIE | E32: A350 | F32: Other | G32: 869 | H32: 2026-09-15 | I32: 1 | J32: ASNA2327-3-3 | K32: Support ASNA2327-3-3 endommagé | L32: ASNA2327-3-3 | P32: =IFERROR(IF(INDEX('Parts to price'!$M$2:$M$92,MATCH(J32,'Parts to price'!$A$2:$A$92,0))="","",INDEX('Parts to price'!$M$2:$M$92,MATCH(J32,'Parts to price'!$A$2:$A$92,0))),"") | Q32: =IF(P32="","",P32*I32) | R32: Support ASNA2327-3-3 endommagé | Support ASNA2327-3-3 endommagé NonConformity 0001 : Type of nonconformity : Structural and Mechanical Assembly * Sur la ligne A350 , poste MECA , l'opérateur a endommagé un support ASNA2327-3-3 lors de l'assemblage de colonnette et de support lacotte. Nous demandons le remplacement du support ASNA2327-3-3 et d'une éventuelle réparation de la structure si elle est endommagée ( à voir lors d'une remplacement du support ) . Task Completed : 0100 `` DEC0 `` Request for Supplier Assessment Decision Taken : External Exchange Text Description :
A33: 216177953 | B33: EXC | C33: Exchange | D33: SERIE | E33: A350 | F33: Other | G33: 817 | H33: 2026-01-20 | I33: 1 | J33: ASNA2328-3-4 | K33: Colonnette de la structure du MIP cassée | L33: ASNA2328-3-4 | P33: =IFERROR(IF(INDEX('Parts to price'!$M$2:$M$92,MATCH(J33,'Parts to price'!$A$2:$A$92,0))="","",INDEX('Parts to price'!$M$2:$M$92,MATCH(J33,'Parts to price'!$A$2:$A$92,0))),"") | Q33: =IF(P33="","",P33*I33) | R33: Colonnette de la structure du MIP cassée | NonConformity 0001 : Type of nonconformity : Structural and Mechanical Assembly * Sur la ligne A350 poste Integration , nous avons endommagé la colonnette ASNA2328-3-4 en appliquant l'OF 1027315420. * Def : Q10-004 : Colonnette cassée. * Demandons remise en conformité du produit Task Completed : 0100 `` DEC0 `` Request for Supplier Assessment Decision Taken : External Exchange Text Description :
A34: 216247653 | B34: EXC | C34: Exchange | D34: SERIE | E34: A350 | F34: Other | G34: 819 | H34: 2026-01-26 | I34: 1 | J34: ASNA2328-3-4 | K34: Colonnette de la structure du MIP cassée | L34: ASNA2328-3-4 | P34: =IFERROR(IF(INDEX('Parts to price'!$M$2:$M$92,MATCH(J34,'Parts to price'!$A$2:$A$92,0))="","",INDEX('Parts to price'!$M$2:$M$92,MATCH(J34,'Parts to price'!$A$2:$A$92,0))),"") | Q34: =IF(P34="","",P34*I34) | R34: Colonnette de la structure du MIP cassée | 567198748 NonConformity 0001 : Type of nonconformity : Structural and Mechanical Assembly * Sur la ligne A350 poste Integration , nous avons endommagé la colonnette ASNA2328-3-4 Veulliez proceder au remplacement de celle-ci. NonConformity 0001 : Type of nonconformity : Structural and Mechanical Assembly * Sur la ligne A350 poste Integration , nous avons endommagé la colonnette ASNA2328-3-4 Veulliez proceder au remplacement de celle-ci. NonConformity 0001 : Type of nonconformity : Broken * Sur la ligne A350 poste Integration , nous avons endommagé la
A35: 216376660 | B35: EXC | C35: Exchange | D35: SERIE | E35: A350 | F35: Other | G35: 823 | H35: 2026-02-09 | I35: 1 | J35: ASNA2328-3-4 | K35: Colonnette de la structure du MIP cassée | L35: ASNA2328-3-4 | P35: =IFERROR(IF(INDEX('Parts to price'!$M$2:$M$92,MATCH(J35,'Parts to price'!$A$2:$A$92,0))="","",INDEX('Parts to price'!$M$2:$M$92,MATCH(J35,'Parts to price'!$A$2:$A$92,0))),"") | Q35: =IF(P35="","",P35*I35) | R35: Colonnette de la structure du MIP cassée | NonConformity 0001 : Type of nonconformity : Broken * Sur la ligne A350 , poste Integration du MSN 823 , nous avons constaté que la colonnette ASNA2328-3-4 est endommagée. Nous demandons le remplacement de celle-ci. * Task Completed : 0100 `` DEC0 `` Request for Supplier Assessment Decision Taken : External Exchange Text Description :
A36: 216227502 | B36: REJ | C36: Rejection | D36: SERIE | E36: A330 | F36: PTVU | G36: 2152 | H36: 2026-01-23 | I36: 1 | J36: COMPOSANT SCRAPE | K36: COMPOSANT SCRAPE | N36: F9251684200000 | O36: ELEC ASSY 255VU | P36: =IFERROR(IF(INDEX('Parts to price'!$M$2:$M$92,MATCH(J36,'Parts to price'!$A$2:$A$92,0))="","",INDEX('Parts to price'!$M$2:$M$92,MATCH(J36,'Parts to price'!$A$2:$A$92,0))),"") | Q36: =IF(P36="","",P36*I36) | R36: COMPOSANT SCRAPE | NonConformity 0001 : Type of nonconformity : Electrical Assembly Installation * le FIRE PUSH A ETE SCAPE REFUS POUR REAPPRO Task Completed : 0100 `` DEC0 `` Decision Taken : REJECT Part Not Fitted Justification : FIRE PUSH SCRAPE * MRP CONTROLER : TROUIS Nathalie +33561936016 MATERIAL GROUP : ++++++++++++++++++++++++++++++++++++++++ * Text Description : - TEL~ Task Completed : 0400 `` ATW0 `` Task Description : Travail effectué - Task Completed : 1000 `` ATQ0 `` Task Description : VU REMIS EN CONFORMITE
A37: 216227907 | B37: REJ | C37: Rejection | D37: SERIE | E37: A330 | F37: PTVU | G37: 2152 | H37: 2026-01-23 | I37: 1 | J37: COMPOSANT SCRAPE | K37: COMPOSANT SCRAPE | N37: F9251684200000 | O37: ELEC ASSY 255VU | P37: =IFERROR(IF(INDEX('Parts to price'!$M$2:$M$92,MATCH(J37,'Parts to price'!$A$2:$A$92,0))="","",INDEX('Parts to price'!$M$2:$M$92,MATCH(J37,'Parts to price'!$A$2:$A$92,0))),"") | Q37: =IF(P37="","",P37*I37) | R37: COMPOSANT SCRAPE | NonConformity 0001 : Type of nonconformity : Electrical Assembly Installation * FIRE PUSH SCRAPE * Text Description : - TEL~ Task Completed : 0400 `` ATW0 `` Task Description : travail effetué - Task Completed : 1000 `` ATQ0 `` Task Description : VU REMIS EN CONFORMITE
A38: 216228052 | B38: REJ | C38: Rejection | D38: SERIE | E38: A330 | F38: PTVU | G38: 2152 | H38: 2026-01-23 | I38: 1 | J38: COMPOSANT SCRAPE | K38: COMPOSANT SCRAPE | N38: F9251684200000 | O38: ELEC ASSY 255VU | P38: =IFERROR(IF(INDEX('Parts to price'!$M$2:$M$92,MATCH(J38,'Parts to price'!$A$2:$A$92,0))="","",INDEX('Parts to price'!$M$2:$M$92,MATCH(J38,'Parts to price'!$A$2:$A$92,0))),"") | Q38: =IF(P38="","",P38*I38) | R38: COMPOSANT SCRAPE | NonConformity 0001 : Type of nonconformity : Electrical Assembly Installation * FIRE PUSH SCRAPE Text Description : - TEL~ Task Completed : 0400 `` ATW0 `` Task Description : Travail effectué - Task Completed : 1000 `` ATQ0 `` Task Description : VU REMIS EN CONFORMITE
A39: 216914342 | B39: REJ | C39: Rejection | D39: SERIE | E39: A330 | F39: PTVU | G39: 2157 | H39: 2026-04-02 | I39: 1 | J39: E0053R14B19PNF | K39: prise non conforme | L39: E0053R14B19PNF | N39: F9251671500000 | O39: ELEC ASSY 241VU | P39: =IFERROR(IF(INDEX('Parts to price'!$M$2:$M$92,MATCH(J39,'Parts to price'!$A$2:$A$92,0))="","",INDEX('Parts to price'!$M$2:$M$92,MATCH(J39,'Parts to price'!$A$2:$A$92,0))),"") | Q39: =IF(P39="","",P39*I39) | R39: prise non conforme | NonConformity 0001 : Type of nonconformity : Electrical Assembly Installation * Sur la ligne A330 , nous constatons qu'il nous a éte fourni un connecteur 14B19SN alors qu'il est demandé au dossier de fabrication un connecteur 14B19PN. nous demandons un connecteur = > E0053R14B19PNF. Task Completed : 0100 `` DEC0 `` Decision Taken : REJECT Part Not Fitted Justification : mauvais connecteur livré * MRP CONTROLER : MATERIAL GROUP : ++++++++++++++++++++++++++++++++++++++++ * Text Description : - TEL~ #TEL~ Task Completed : 0150 `` DO00 `` Task Description : NC Traité sur SO1
A40: 217687557 | B40: REJ_RW | C40: Rejection with a rework order | D40: SERIE | E40: A330 | F40: PTVU | G40: 2164 | H40: 2026-06-26 | I40: 1 | J40: E0053R14B19PNF | K40: Enfichage prise 681VC impossible | L40: E0053R14B19PNF | M40: 681VC | N40: F9251671300000 | O40: ELEC ASSY 145VU | P40: =IFERROR(IF(INDEX('Parts to price'!$M$2:$M$92,MATCH(J40,'Parts to price'!$A$2:$A$92,0))="","",INDEX('Parts to price'!$M$2:$M$92,MATCH(J40,'Parts to price'!$A$2:$A$92,0))),"") | Q40: =IF(P40="","",P40*I40) | R40: Enfichage prise 681VC impossible | NonConformity 0001 : Type of nonconformity : Incorrect connector * Lors de l'enfichage par la production des câbles sur la prise 681VC du 154VU MSN 2164 , il est constaté que plusiueurs borne ne permettent pas l'enfichage des contacts. * Prise REF : E0053R14B19PNF * Merci de changer la prise. Text Description : - TEL~ #TEL~ Task Completed : 0200 `` DO00 `` Task Description : NC prise en compte par OF 1030158587. - Task Completed : 1000 `` ATQ0 `` Task Description : remis en conformité
...

Sheet Not charged to FTO2
A1: NC | B1: Decision | C1: Liability | D1: Phase | E1: Product | F1: Created | G1: Part reference / FIN / name | H1: Part (as named in the NC)
A2: 216366914 | B2: REJ_RW | C2: 0000314592 | D2: SERIE | E2: PTVU | F2: 2026-02-06 | G2: 314 VU STRUCTURE PEINTURE CADRE NC | H2: 314 VU STRUCTURE peinture cadre NC
A3: 216165997 | B3: REJ_RW | C3: FFF1 | D3: REC | E3: 125VU | F3: 2026-01-19 | G3: 6374845400 | H3: ETEC 125VU ENDOMMAGE
A4: 217128024 | B4: REJ_RW | C4: 249637 | D4: SERIE | E4: PTVU | F4: 2026-04-24 | G4: ABS0064-01 | H4: NC TEST DEFAUT CONTINUITE
A5: 216558859 | B5: EXC | C5: 148971 | D5: SERIE | E5: Other | F5: 2026-02-26 | G5: ABS0901R045 | H5: Collier de tuyauterie non serré
A6: 216969942 | B6: REJ | C6: 0000154965 | D6: SERIE | E6: PTVU | F6: 2026-04-09 | G6: ABS0951C3LM073 | H6: Indicateur HS
A7: 216062470 | B7: EXC | C7: SPAHUBC | D7: SERIE | E7: Other | F7: 2026-01-07 | G7: ABS2268C025A | H7: ATT*CKPT*C4/5*G*Manchon abîmé MIP*SD@*
A8: 216312177 | B8: EXC | C8: 147026 | D8: SERIE | E8: 743VU | F8: 2026-02-02 | G8: ASNA2551A01 | H8: MANQUE INSERT ASNA2551A01
A9: 216785207 | B9: EXC | C9: 147026 | D9: SERIE | E9: 743VU | F9: 2026-03-20 | G9: ASNA2551A01 | H9: INSERT ASNA2551A01 NON CONFORME
A10: 216194905 | B10: REJ | C10: 0000146662 | D10: SERIE | E10: MIP A350 | F10: 2026-01-21 | G10: BARRETTES TORDUES | H10: Barrettes tordues
A11: 217755445 | B11: EXC | C11: 180892 | D11: SERIE | E11: Other | F11: 2026-07-03 | G11: COCK*G/D*C06/09*L10*RIVETAGE OHP NC | H11: COCK*G/D*C06/09*L10*Rivetage OHP NC
A12: 217584160 | B12: EXC | C12: 150597 | D12: SERIE | E12: 300VU | F12: 2026-06-17 | G12: CÔTES MEUBLE 300VU HORS TOLÉRENCES | H12: Côtes Meuble 300VU hors tolérences
... A113: 216184552 | B113: EXC | C113: 150597 | D113: SERIE | E113: 300VU | F113: 2026-01-20 | G113: VISSERIE COURTES DANS INSERTS STRUCTURE | H113: Visserie courtes dans inserts structure
