Workbook

Sheet ReadMe
A1: CNQ investigation workbook
A2: FTO2 / Airbus Electric Center, quality. Built 19 October 2026.
A4: Two calculations
A5: 1. NC cost of non-quality: one cost per NC (level 3 of the CNQ model). The operator's aléa that leads to an NC is part of it (the 30-min alert step).
A6: 2. Disruption block, shown beside it and never added inside it: quality aléas that did not lead to an NC (option B), plus other-kind aléas you decide count as quality (M1).
A8: How to use
A9: Start with the Checklist tab: one line per check, priority, question, where to look, and a link to its tab. Each tab lists the orders, NCs or aléas to look at.
A10: Yellow cells (blue text) are yours to fill: Y / N answers, findings, figures you find. Totals and the Figures tab recalculate from them.
A11: Example: in D_Block, an aléa whose NC was written by ERMA gets N in 'Keep in block?'; the block total in Figures drops by its hours.
A12: Example: in H3, typing 3 in 'Repair hours at the customer' replaces the model's rework for that return by 3 h x the rate in Figures!C4.
A14: Sources
A15: Work orders: SAP operations confirmed 1 Sep - 1 Oct 2026 (order type S03 = rework orders). Planned time = standard value in IM (1/100 h); confirmed times equal planned for 98% of operations.
... A18: CNQ model: cnq_handoever, version cnq-2026.10.19. Scripts that rebuild every list: 07_scripts/wo_disruption (build_checklist.py builds this file).

Sheet Checklist
A1: CNQ investigation checklist
A2: Built 19 October 2026 from the work orders (Sept 2026), the MES disruptions (Jan-Sep 2026) and the NC files (2025, 2026). One line per check; each has its own tab.
A4: Yellow cells are yours to fill (Status, Finding, Decision here; the yellow columns in each tab). Example of a filled line: Status 'Done' · Finding 'Orders are created by support without times when the rework is done by the test team' · Decision 'Use the model for orders with no time'.
A6: ID | B6: Priority | C6: Check | D6: What we know | E6: Question to answer | F6: Where to look / who to ask | G6: Tab | H6: Status | I6: Finding | J6: Decision
A7: H1 | B7: High | C7: Rework done without an NC (shop floor) | D7: 105 rework orders, about 181 planned h in September, no NC behind them: quality-team time, cable cutting, rework after test with no NC, cable / label remakes with no NC reference, formboard checks. | E7: Which are non-quality? Which should have had an NC? | F7: Rework order texts in SAP; line leaders; quality | G7: H1_ReworkNoNC | H7: To do
A8: H2 | B8: High | C8: Quality team time booked on rework orders | D8: 2 orders, 70.5 h in September (A350 and A330 lines), incl. 15 h 'Gestion NC retours clients + analyse' and 4 h 'Alerte qualité'. | E8: Monthly? Which hours are NC handling? Overlap with the model's writing / support steps? | F8: Quality line managers (4QEH5I07, 4QEH1I07); SAP orders | G8: H2_QualityTime | H8: To do
A9: H3 | B9: High | C9: Customer returns: actual cost incl. work at the customer | D9: 69 returns in 2026, model cost about 10,250 EUR. Repair happens at the customer (FNZ1 kits, FFF1 via REC orders); analysis, transport, penalties not counted. | E9: Repair hours at the customer, analysis hours, transport / kits, penalties. Put the customer's alert back? | F9: Quality (customer returns), TOF / FNZ1 / FFF1 contacts, REC | G9: H3_CustomerReturns | H9: To do
A10: H4 | B10: High | C10: BF24 / BF20 cable cutting for stock | D10: 37 orders, 78 h, 2,600 cables cut in September for the PTVU line, after disruptions on Elec ABC quantities and missing BF24. | E10: Non-quality, or a definition / kitting problem? | F10: Methods (Elec ABC), A330 print room, PTVU line leader | G10: H4_CableCutting | H10: To do
A11: H5 | B11: High | C11: Reworked NCs with no rework order | D11: 47 NCs (2026 and 2025) decided 'rework' with nothing in linked_document. | E11: Fixed on the spot, or an order that was never linked? | F11: SAP: NC and orders on the same work order / MSN | G11: H5_NCsNoOrder | H11: To do
A12: H6 | B12: High | C12: Rework orders with no planned time | D12: 79 of 614 rework orders in September have no standard value (63 of 249 on the shop floor). | E12: Why no time? How should those NCs be costed? | F12: Methods / technical support who create the orders | G12: H6_OrdersNoTime | H12: To do
A13: H7 | B13: High | C13: Disruption export complete? | D13: Exactly 2,500 rows, newest first, 5 Jan 08:57 to 30 Sep 23:31. Starts on the plant's restart day, so probably complete. | E13: Re-export Jan-Mar and compare 5 January; look for a row limit. | F13: Skywise / Contour export; MES | G13: H7_DisruptExport | H13: To do
A14: M1 | B14: Medium | C14: Other aléas that look like quality | D14: 107 logistics / work-order / line aléas whose text reads like a quality problem, in 5 groups. | E14: Yes / no per group (no need to read them all). | F14: This workbook | G14: M1_QualityLike | H14: To do
A15: M4 | B15: Medium | C15: ERMA aléas inside the disruption block | D15: 19 of the 108 'no NC' quality aléas are on the MIP / 1101VB, where ERMA writes NCs. Their NC may exist but be excluded with ERMA. | E15: Put N in D_Block for those that have an ERMA NC. | F15: Skywise NCs on the same work order | G15: D_Block | H15: To do
A16: M2 | B16: Medium | C16: Rework orders naming NCs we do not have | D16: 40 orders, about 27 h, name 2026 NCs that are not in our exports. | E16: Plant / liability / writer of those NCs: out of scope, or missing from the export? | F16: Skywise NC lookup | G16: M2_NCsNotHeld | H16: To do
A17: M3 | B17: Medium | C17: Exceptional NCs (not for the presentation) | D17: 4 NCs where the order plans far more than the model, e.g. 34 h of cable reprinting on one NC line. | E17: Is the planned time right? Should such NCs be costed from their order? | F17: You | G17: M3_Exceptional | H17: To do
A18: L1 | B18: Low | C18: MSN 700/701 work (IEVB) | D18: 74 orders, 217 h in September, flight-test installation work. | E18: Confirm out of scope. | F18: Flight-test / IEV team | G18: Later | H18: To do
A19: L2 | B19: Low | C19: Change 5 kept for later | D19: Two defect classes missing from the time table (about 0 EUR). | E19: Apply when convenient. | F19: - | G19: Later | H19: To do
A21: Progress | C21: =COUNTIF(H7:H19,"Done")&" done, "&COUNTIF(H7:H19,"In progress")&" in progress, "&COUNTIF(H7:H19,"To do")&" to do" -> 0 done, 0 in progress, 13 to do

Sheet Figures
A1: CNQ figures as of 19 October 2026
A2: Model cnq-2026.10.19 (alert only when an operator raises one; connection errors 35 then 15 min; internal NCs x 2). Blue = values from the analysis, black = formulas.
A4: Hourly rate used for hours (EUR/h) | C4: 50 | D4: Official France rate used by the CNQ model (RATE_STANDARD). Change it here and every EUR figure in this workbook follows.
A6: 1. NC cost of non-quality (level 3)
A7: Pack reference data, 5 Jan - 6 Jul 2026 (595 NCs) | C7: 121503 | D7: cnq_handoever/tests/expected_totals.json (parser v4.7 data)
A8: 2026 Feb-Sep, raised at FTO2 (695 NCs) | C8: 142151 | D8: Parser v4.8 on the dashboard export + missing IDs; January left out (export cut)
A9: 2025 Jan-Dec, raised at FTO2, without ERMA (818 NCs) | C9: 168633 | D9: 2025 NC file; ERMA NCs left out to match the 2026 pipeline
A10: Customer returns 2026, Jan-Sep (69 NCs), model today | C10: 10250 | D10: Raised at other plants, FTO2 liable; see H3 for the actual cost
A11: Customer returns 2026 with the findings entered in H3 | C11: =H3_CustomerReturns!$R$77 -> 10250 | D11: Follows H3 'Cost with findings'
A13: 2. Disruption block (option B): quality aléas with no NC
A14: Declared quality aléas kept (D_Block), Jan-Sep 2026: hours lost | C14: =SUMIFS(D_Block!$G$7:$G$114,D_Block!$K$7:$K$114,"<>N")/60 -> 91.2
A15: of which Feb-Sep (same period as the 2026 NC cost) | C15: =SUMIFS(D_Block!$G$7:$G$114,D_Block!$K$7:$K$114,"<>N",D_Block!$C$7:$C$114,">=202602")/60 -> 64.933333
A16: Other-kind aléas counted as quality (M1 groups marked Y): hours lost | C16: =SUMIFS(M1_QualityLike!$F$16:$F$122,M1_QualityLike!$I$16:$I$122,"Y")/60 -> 0
A17: Disruption block, Jan-Sep 2026 (EUR) | C17: =(C14+C16)*Figures!$C$4 -> 4560 | D17: Hours lost x rate. Shown beside the NC cost, never added inside it.
A19: 3. Known, not counted (scope or under investigation)
A20: REC rework orders at the FAL, September 2026: planned hours | C20: 746 | D20: Out of scope as decided (REC)
A21: in EUR | C21: =C20*Figures!$C$4 -> 37300
A22: ERMA NCs 2025, FTO2 liable (184 NCs): level 3 EUR | C22: 44472 | D22: Out of scope as decided (ERMA); new model
A23: Shop-floor rework with no NC, September 2026: planned hours (H1) | C23: =H1_ReworkNoNC!$E$112 -> 180.76 | D23: Under investigation (H1)
A24: of which marked non-quality in H1: hours | C24: =SUMIFS(H1_ReworkNoNC!$E$7:$E$111,H1_ReworkNoNC!$I$7:$I$111,"Y") -> 0
A25: of which marked non-quality in H1: EUR | C25: =C24*Figures!$C$4 -> 0

Sheet H1_ReworkNoNC
A1: H1. Rework orders on the FTO2 shop floor with no NC behind them (September 2026)
A2: S03 rework orders on FTO2 work centres (REC, flight test, regularisation and A400M excluded) that no NC links to and that name no NC number.
A4: For each order (or each group, using the filter): is it non-quality, and should an NC exist? Rework after test and cable remakes with no NC are the most likely 'missing NCs'. Planned hours are SAP standard values in IM (1/100 h), converted to hours.
A6: Rework order | B6: Programme | C6: MSN | D6: Work centre(s) | E6: Planned h | F6: Group (my reading) | G6: Named in disruption | H6: What the order says | I6: Non-quality? (Y/N) | J6: Should an NC have been written? (Y/N) | K6: Comment
A7: 1031148483 | B7: A330 | C7: 2166 | D7: Attestation de conformitÃ© / Contrôle impression / Impression | E7: 13.26 | F7: Cable cutting for stock (see H4) | H7: Attestation de conformité || Inspection Qualité || Débiter câbles BF24 Débiter câbles BF24 Veuillez débiter du BF24 => 3 fagots de 50 câbles de 100cm
A8: 1030956049 | B8: A330 | C8: 2169 | D8: Contrôle impression / Impression | E8: 3.42 | F8: Cable cutting for stock (see H4) | H8: Inspection Qualité || Débiter câbles BF24 et BF20 Débiter câbles BF24 et BF20 Veuillez débiter du BF24 50 câbles de 100cm Veuillez débiter du BF24 50 câbles de 80cm Veuillez débiter du BF20 50 câbles de 80cm
A9: 1030956972 | B9: A330 | C9: 2169 | D9: Impression | E9: 3.42 | F9: Cable cutting for stock (see H4) | H9: Débiter câbles BF24 et BF20 Débiter câbles BF24 et BF20 Veuillez débiter du BF24 50 câbles de 100cm Veuillez débiter du BF24 50 câbles de 80cm Veuillez débiter du BF20 50 câbles de 80cm
A10: 1030957008 | B10: A330 | C10: 2169 | D10: Contrôle impression / Impression | E10: 3.42 | F10: Cable cutting for stock (see H4) | H10: Inspection Qualité || Débiter câbles BF24 et BF20 Débiter câbles BF24 et BF20 Veuillez débiter du BF24 50 câbles de 100cm Veuillez débiter du BF24 50 câbles de 80cm Veuillez débiter du BF20 50 câbles de 80cm
A11: 1030957018 | B11: A330 | C11: 2169 | D11: Impression | E11: 3.42 | F11: Cable cutting for stock (see H4) | H11: Débiter câbles BF24 et BF20 Débiter câbles BF24 et BF20 Veuillez débiter du BF24 50 câbles de 100cm Veuillez débiter du BF24 50 câbles de 80cm Veuillez débiter du BF20 50 câbles de 80cm
A12: 1030957042 | B12: A330 | C12: 2169 | D12: Impression | E12: 3.42 | F12: Cable cutting for stock (see H4) | H12: Débiter câbles BF24 et BF20 Débiter câbles BF24 et BF20 Veuillez débiter du BF24 50 câbles de 100cm Veuillez débiter du BF24 50 câbles de 80cm Veuillez débiter du BF20 50 câbles de 80cm
A13: 1030957054 | B13: A330 | C13: 2169 | D13: Impression | E13: 3.42 | F13: Cable cutting for stock (see H4) | H13: Débiter câbles BF24 et BF20 Débiter câbles BF24 et BF20 Veuillez débiter du BF24 50 câbles de 100cm Veuillez débiter du BF24 50 câbles de 80cm Veuillez débiter du BF20 50 câbles de 80cm
A14: 1030957059 | B14: A330 | C14: 2169 | D14: Impression | E14: 3.42 | F14: Cable cutting for stock (see H4) | H14: Débiter câbles BF24 et BF20 Débiter câbles BF24 et BF20 Veuillez débiter du BF24 50 câbles de 100cm Veuillez débiter du BF24 50 câbles de 80cm Veuillez débiter du BF20 50 câbles de 80cm
A15: 1030957073 | B15: A330 | C15: 2169 | D15: Attestation de conformitÃ© / Contrôle impression / Impression | E15: 3.42 | F15: Cable cutting for stock (see H4) | H15: Attestation de conformité || Inspection Qualité || Débiter câbles BF24 et BF20 Débiter câbles BF24 et BF20 Veuillez débiter du BF24 50 câbles de 100cm Veuillez débiter du BF24 50 câbles de 80cm Veuillez débiter du BF20 50 câbles de 80cm
A16: 1030957083 | B16: A330 | C16: 2169 | D16: Contrôle impression / Impression | E16: 3.42 | F16: Cable cutting for stock (see H4) | H16: Inspection Qualité || Débiter câbles BF24 et BF20 Débiter câbles BF24 et BF20 Veuillez débiter du BF24 50 câbles de 100cm Veuillez débiter du BF24 50 câbles de 80cm Veuillez débiter du BF20 50 câbles de 80cm
A17: 1031218410 | B17: A330 | C17: 2171 | D17: Attestation de conformitÃ© / Contrôle impression / Impression | E17: 2.26 | F17: Cable cutting for stock (see H4) | H17: Inspection Qualité || Attestation de conformité || Débiter câbles BF24 Débiter câbles BF24 Veuillez débiter du BF24 => 2 fagots de 50 câbles de 100cm
A18: 1031218471 | B18: A330 | C18: 2171 | D18: Attestation de conformitÃ© / Contrôle impression / Impression | E18: 2.26 | F18: Cable cutting for stock (see H4) | H18: Inspection Qualité || Attestation de conformité || Débiter câbles BF24 Débiter câbles BF24 Veuillez débiter du BF24 => 2 fagots de 50 câbles de 100cm
... A111: 1031263387 | B111: A320 | C111: 7877 | D111: Attestation Conformité / Fabrication Harnais Electrique / Inspection qualité | E111: 0 | F111: Rework after test, no NC written | H111: Attestation de conformité || Contrôle || Dépose NSA940692-1 non conforme Dépose NSA940692-1 non conforme Merci de déposer le harnais UW520 NSA940692-1, 202ZU2 || Repose NSA940692-1 conforme Repose NSA940692-1 conforme Merci de procéder à la repose du harnais UW520 NSA940692-1 W1-Enc || PREPARATION / ANALYSE DOSSIER
A112: Total planned h | E112: =SUM(E7:E111) -> 180.76 | F112: ="Marked non-quality: "&TEXT(SUMIFS(E7:E111,I7:I111,"Y"),"0.0")&" h" -> Marked non-quality: 0.0 h

Sheet H2_QualityTime
A1: H2. Quality team time booked on rework orders (September 2026)
A2: Two S03 orders on quality work centres look like the quality team's time sheet for the month: one for the A350 line, one for the A330 line.
A4: Questions: Is there one such order per line every month? Who books on it? Which operations are NC handling (and so CNQ), and which are normal quality work (QA qualification, production support)? Does any of it overlap the model's 'writing the NC' (30/60 min) or 'technical support' (60 min) steps?
A6: Order | B6: Programme / MSN | C6: Work centre | D6: Op | E6: Operation | F6: Long text | G6: Planned h | H6: NC-related? (Y/N) | I6: Already in the model's steps? (writing / support / none) | J6: Comment
A7: 1031225552 | B7: A330 / 2172 | C7: 4QEH1I07 | D7: 10 | E7: SO et AD-HOC | G7: 4
A8: 1031225552 | B8: A330 / 2172 | C8: 4QEH1I07 | D8: 20 | E8: Passage de QA 1ere attribution et renouv | F8: Passage de QA 1ere attribution et renouvellement | G8: 5
A9: 1031225552 | B9: A330 / 2172 | C9: 4QEH1I07 | D9: 30 | E9: REVUE QA | G9: 1
A10: 1031225552 | B10: A330 / 2172 | C10: 4QEH1I07 | D10: 40 | E10: ALERTE QUALITE SUITE A RETOUR CLIENT OU | F10: ALERTE QUALITE SUITE A RETOUR CLIENT OU ALERTE NOE | G10: 1
A11: 1031225552 | B11: A330 / 2172 | C11: 4QEH1I07 | D11: 50 | E11: ACCOMPAGNEMENT PRODUCTION | G11: 1.5
A12: 1031225552 | B12: A330 / 2172 | C12: 4QEH1I07 | D12: 60 | E12: RECHERCHE IBM | G12: 2
A13: 1031225552 | B13: A330 / 2172 | C13: 4QEH1I07 | D13: 70 | E13: POINTS PTVU / MFT | G13: 5
A14: 1031225552 | B14: A330 / 2172 | C14: 4QEM0I01 | D14: 9995 | E14: Attestation de conformité | G14: 0
A15: 1031243823 | B15: A350 / 872 | C15: 4QEH5I07 | D15: 10 | E15: SO | G15: 3
A16: 1031243823 | B16: A350 / 872 | C16: 4QEH5I07 | D16: 20 | E16: ACCOMPAGNEMENT PROD / QA / L2 / TL | G16: 20
A17: 1031243823 | B17: A350 / 872 | C17: 4QEH5I07 | D17: 30 | E17: ACCOMPAGNEMENT ME | G17: 1
A18: 1031243823 | B18: A350 / 872 | C18: 4QEH5I07 | D18: 40 | E18: Gestion des parachèvements | G18: 2
A19: 1031243823 | B19: A350 / 872 | C19: 4QEH5I07 | D19: 50 | E19: NC cable / Interne | G19: 3
A20: 1031243823 | B20: A350 / 872 | C20: 4QEH5I07 | D20: 60 | E20: Gestion NC Fournisseur et/ou client + a | G20: 2
A21: 1031243823 | B21: A350 / 872 | C21: 4QEH5I07 | D21: 70 | E21: Gestion NC retours clients + analyse | F21: Gestion NC retours clients + analyse lité + admin | G21: 15
A22: 1031243823 | B22: A350 / 872 | C22: 4QEH5I07 | D22: 80 | E22: Controle finale MDCD + accompagnement MD | G22: 1
A23: 1031243823 | B23: A350 / 872 | C23: 4QEH5I07 | D23: 90 | E23: Alerte qualité | G23: 4
A24: 1031243823 | B24: A350 / 872 | C24: 4QEH0I01 | D24: 9995 | E24: Attestation de conformité | G24: 0
A25: Total planned h | G25: =SUM(G7:G24) -> 70.5 | H25: =SUMIFS(G7:G24,H7:H24,"Y") -> 0
H26: h marked NC-related

Sheet H3_CustomerReturns
A1: H3. Customer returns: the actual cost, including the work done at the customer
A2: Customer-return NCs where FTO2 is liable, created in 2026. We are the direct cause, so every cost we can find counts, even outside the plant.
A4: What the model counts today: writing the NC, technical support, re-check, and the rework estimated at FTO2's times (no operator alert since 19 Oct). What it does not count: the repair time actually spent at the customer, the analysis (8D), transport, kits, penalties. Fill what you find in the yellow columns; 'Cost with findings' replaces the model's rework by the real repair hours when you enter them, and adds the rest.
A5: What we already know: FNZ1 returns (cockpit 'mauvais backshell') get an FTO2 rework order that only checks the kit sent to Montoir-de-Bretagne (0 h planned). Two FFF1 returns ('312VU endommagé') are linked to REC rework orders at the FAL (0.5 and 0.8 h planned). In September the quality team's A350 order booked 15 h of 'Gestion NC retours clients + analyse' for 8 A350 returns.
A7: NC | B7: Created | C7: Raised at plant | D7: Programme | E7: MSN | F7: What was found | G7: Decision | H7: Defect lines | I7: Model cost now (EUR) | J7: of which rework at FTO2 times (EUR) | K7: Rework order(s) linked | L7: Planned h on that order (Sept file) | M7: Repair hours at the customer | N7: Analysis / 8D hours | O7: Transport, kit, logistics (EUR) | P7: Penalties, other (EUR) | Q7: Source of the figures | R7: Cost with findings (EUR)
A8: 216060610 | B8: 2026-01-07 | C8: FNZ1 | D8: MT | E8: 159 | F8: Cab*G*C17*L1/2*Prise 624VC non conforme | G8: RWK | H8: 0 | I8: 150 | J8: 50 | K8: 1028164740, 1028176622 | R8: =I8-IF(ISNUMBER(M8),J8-M8*Figures!$C$4,0)+N(N8)*Figures!$C$4+N(O8)+N(P8) -> 150
A9: 216172114 | B9: 2026-01-19 | C9: FNZ1 | D9: MT | E9: 160 | F9: OHP-G Dérivation mal positionnée 2400VB | G9: RWK | H9: 0 | I9: 150 | J9: 50 | K9: 1028305824, 1028306604 | R9: =I9-IF(ISNUMBER(M9),J9-M9*Figures!$C$4,0)+N(N9)*Figures!$C$4+N(O9)+N(P9) -> 150
A10: 216217484 | B10: 2026-01-22 | C10: FFF1 | D10: A330 | E10: 2142 | F10: Vis cassé dans alésage | G10: RWK | H10: 1 | I10: 159.18 | J10: 58.33 | K10: 1028140433 | R10: =I10-IF(ISNUMBER(M10),J10-M10*Figures!$C$4,0)+N(N10)*Figures!$C$4+N(O10)+N(P10) -> 159.18
A11: 216225110 | B11: 2026-01-23 | C11: FFF1 | D11: A330 | E11: 2142 | F11: Disjoncteur 2RE1 cassée | G11: RWK | H11: 1 | I11: 166.67 | J11: 66.67 | K11: 1028174479 | R11: =I11-IF(ISNUMBER(M11),J11-M11*Figures!$C$4,0)+N(N11)*Figures!$C$4+N(O11)+N(P11) -> 166.67
A12: 216308985 | B12: 2026-02-02 | C12: FFF1 | D12: A330 | E12: 2121 | F12: Circuit breaker ATC broken | G12: RWK | H12: 1 | I12: 166.67 | J12: 66.67 | K12: 1028253666 | R12: =I12-IF(ISNUMBER(M12),J12-M12*Figures!$C$4,0)+N(N12)*Figures!$C$4+N(O12)+N(P12) -> 166.67
A13: 216313341 | B13: 2026-02-02 | C13: FFF1 | D13: A320 | E13: 13212 | F13: Damaged 2797VC socket | G13: RWK | H13: 1 | I13: 166.67 | J13: 66.67 | R13: =I13-IF(ISNUMBER(M13),J13-M13*Figures!$C$4,0)+N(N13)*Figures!$C$4+N(O13)+N(P13) -> 166.67
A14: 216340381 | B14: 2026-02-04 | C14: FNZ1 | D14: A350 | E14: 813 | F14: CKPT*C1/3*R0/1*D*Collier HS MIP*SD@* | G14: RWK | H14: 1 | I14: 166.67 | J14: 66.67 | K14: 1028304301, 1028304491 | R14: =I14-IF(ISNUMBER(M14),J14-M14*Figures!$C$4,0)+N(N14)*Figures!$C$4+N(O14)+N(P14) -> 166.67
A15: 216394948 | B15: 2026-02-10 | C15: FNZ1 | D15: A350 | E15: 809 | F15: CKPT*C4/5*G*Montage x2 non conf MIP*RL* | G15: RWK | H15: 1 | I15: 166.67 | J15: 66.67 | K15: 1028411423, 1028411928 | R15: =I15-IF(ISNUMBER(M15),J15-M15*Figures!$C$4,0)+N(N15)*Figures!$C$4+N(O15)+N(P15) -> 166.67
A16: 216457592 | B16: 2026-02-16 | C16: FFF1 | D16: A330 | E16: 2150 | F16: vis manquante 312VU | G16: RWK | H16: 1 | I16: 150 | J16: 50 | K16: 1028454717 | R16: =I16-IF(ISNUMBER(M16),J16-M16*Figures!$C$4,0)+N(N16)*Figures!$C$4+N(O16)+N(P16) -> 150
A17: 216501197 | B17: 2026-02-20 | C17: FNZ1 | D17: A350 | E17: 815 | F17: CKPT*C4/5*D*Orientation Backshel NC*SD@* | G17: RWK | H17: 1 | I17: 166.85 | J17: 66.67 | K17: 1028522896 | R17: =I17-IF(ISNUMBER(M17),J17-M17*Figures!$C$4,0)+N(N17)*Figures!$C$4+N(O17)+N(P17) -> 166.85
A18: 216573781 | B18: 2026-02-27 | C18: DST1 | D18: A320 | E18: 13259 | F18: NoE from Supplier | G18: RWK | H18: 1 | I18: 150 | J18: 50 | K18: 1028699551, 1028699569 | R18: =I18-IF(ISNUMBER(M18),J18-M18*Figures!$C$4,0)+N(N18)*Figures!$C$4+N(O18)+N(P18) -> 150
A19: 216640513 | B19: 2026-03-06 | C19: FFF1 | D19: A350 | E19: 814 | F19: CRG1-FR39/40-LH-BACKSHELL-BE | G19: RWK | H19: 1 | I19: 153.58 | J19: 50 | K19: 1028741420 | R19: =I19-IF(ISNUMBER(M19),J19-M19*Figures!$C$4,0)+N(N19)*Figures!$C$4+N(O19)+N(P19) -> 153.58
A20: 216642382 | B20: 2026-03-06 | C20: FFF1 | D20: A350 | E20: 797 | F20: FOD-WINGBOX-LHS-RIB2-521DB-IN-FOD-HA | G20: PNC | H20: 1 | I20: 100 | J20: 0 | R20: =I20-IF(ISNUMBER(M20),J20-M20*Figures!$C$4,0)+N(N20)*Figures!$C$4+N(O20)+N(P20) -> 100
A21: 216650708 | B21: 2026-03-07 | C21: AFM1 | D21: A320 | E21: 13117 | F21: ESAO/ENG 2/SERVICE INTERPHONE INOP | G21: RWK | H21: 2 | I21: 191.67 | J21: 91.67 | K21: 1028735698 | R21: =I21-IF(ISNUMBER(M21),J21-M21*Figures!$C$4,0)+N(N21)*Figures!$C$4+N(O21)+N(P21) -> 191.67
A22: 216651361 | B22: 2026-03-08 | C22: AFM1 | D22: A320 | E22: 13143 | F22: ESAO/GTI/1GA Circuit breaker tripping | G22: RWK | H22: 1 | I22: 166.67 | J22: 66.67 | R22: =I22-IF(ISNUMBER(M22),J22-M22*Figures!$C$4,0)+N(N22)*Figures!$C$4+N(O22)+N(P22) -> 166.67
A23: 216666114 | B23: 2026-03-09 | C23: FFF1 | D23: A350 | E23: 700 | F23: ELEC/CARGO1/FTI/BONDINGBRAID/DISCONNECT | G23: RWK | H23: 1 | I23: 150 | J23: 50 | R23: =I23-IF(ISNUMBER(M23),J23-M23*Figures!$C$4,0)+N(N23)*Figures!$C$4+N(O23)+N(P23) -> 150
A24: 216668677 | B24: 2026-03-10 | C24: FNZ1 | D24: A350 | E24: 817 | F24: CKPT*C9*L22*D*Détrompeur cassé*MV* | G24: RWK | H24: 1 | I24: 166.67 | J24: 66.67 | K24: 1028762697, 1028762835 | R24: =I24-IF(ISNUMBER(M24),J24-M24*Figures!$C$4,0)+N(N24)*Figures!$C$4+N(O24)+N(P24) -> 166.67
A25: 216672801 | B25: 2026-03-10 | C25: A-DU | D25: A320 | E25: 13143 | F25: ESAO/GTI/1GA Circuit Breaker Tripping | G25: RWK | H25: 2 | I25: 191.67 | J25: 91.67 | K25: 1028762098 | R25: =I25-IF(ISNUMBER(M25),J25-M25*Figures!$C$4,0)+N(N25)*Figures!$C$4+N(O25)+N(P25) -> 191.67
A26: 216678821 | B26: 2026-03-10 | C26: FNZ1 | D26: A350 | E26: 823 | F26: CKPT*C6*L24/25*D*Prise harnais NC*BA@* | G26: RWK | H26: 1 | I26: 166.67 | J26: 66.67 | R26: =I26-IF(ISNUMBER(M26),J26-M26*Figures!$C$4,0)+N(N26)*Figures!$C$4+N(O26)+N(P26) -> 166.67
A27: 216696565 | B27: 2026-03-11 | C27: FFF1 | D27: A350 | E27: 700 | F27: ELEC/CARGO1/HARNESS/CLASH/ESN/FTI | G27: RWK | H27: 1 | I27: 150 | J27: 50 | R27: =I27-IF(ISNUMBER(M27),J27-M27*Figures!$C$4,0)+N(N27)*Figures!$C$4+N(O27)+N(P27) -> 150
A28: 17063910 | B28: 2026-03-12 | C28: 51 | D28: A330 | E28: 2151 | F28: ERGOT WARNING HORN H.S. | G28: REJ | H28: 1 | I28: 100 | J28: 0 | R28: =I28-IF(ISNUMBER(M28),J28-M28*Figures!$C$4,0)+N(N28)*Figures!$C$4+N(O28)+N(P28) -> 100
A29: 216707983 | B29: 2026-03-12 | C29: FFF1 | D29: A350 | E29: 700 | F29: NC.ITEM/CARGO1/ATTENUATOR/CAP | G29: RWK | H29: 1 | I29: 150 | J29: 50 | K29: 1028923893 | R29: =I29-IF(ISNUMBER(M29),J29-M29*Figures!$C$4,0)+N(N29)*Figures!$C$4+N(O29)+N(P29) -> 150
A30: 216748577 | B30: 2026-03-17 | C30: FFF1 | D30: A350 | E30: 804 | F30: Bite Test RAIMS Fault Code 2350F092 | G30: RWK | H30: 1 | I30: 150 | J30: 50 | K30: 1029047483 | R30: =I30-IF(ISNUMBER(M30),J30-M30*Figures!$C$4,0)+N(N30)*Figures!$C$4+N(O30)+N(P30) -> 150
A31: 216750973 | B31: 2026-03-17 | C31: FFF1 | D31: A330 | E31: 2145 | F31: Inversion de câble sur le 9PH | G31: RWK | H31: 1 | I31: 170.83 | J31: 70.83 | K31: 1028908230 | R31: =I31-IF(ISNUMBER(M31),J31-M31*Figures!$C$4,0)+N(N31)*Figures!$C$4+N(O31)+N(P31) -> 170.83
A32: 216854475 | B32: 2026-03-26 | C32: FFF1 | D32: A350 | E32: 802 | F32: BF4-FR63/64-197AT-LH-ABS2210B301F-DC | G32: RWK | H32: 1 | I32: 159.18 | J32: 58.33 | R32: =I32-IF(ISNUMBER(M32),J32-M32*Figures!$C$4,0)+N(N32)*Figures!$C$4+N(O32)+N(P32) -> 159.18
A33: 216926613 | B33: 2026-04-03 | C33: FFF1 | D33: A330 | E33: 2145 | F33: Rampe cassée | G33: RWK | H33: 1 | I33: 159.18 | J33: 58.33 | K33: 1029183367 | R33: =I33-IF(ISNUMBER(M33),J33-M33*Figures!$C$4,0)+N(N33)*Figures!$C$4+N(O33)+N(P33) -> 159.18
A34: 216937725 | B34: 2026-04-05 | C34: FFF1 | D34: A330 | E34: 2148 | F34: FIN breakers érronés | G34: RWK | H34: 1 | I34: 166.67 | J34: 66.67 | R34: =I34-IF(ISNUMBER(M34),J34-M34*Figures!$C$4,0)+N(N34)*Figures!$C$4+N(O34)+N(P34) -> 166.67
A35: 216947614 | B35: 2026-04-07 | C35: FFF1 | D35: A330 | E35: 2149 | F35: Interference 313VU/265VT structure | G35: RWK | H35: 1 | I35: 150 | J35: 50 | K35: 1029181729 | R35: =I35-IF(ISNUMBER(M35),J35-M35*Figures!$C$4,0)+N(N35)*Figures!$C$4+N(O35)+N(P35) -> 150
A36: 216981246 | B36: 2026-04-09 | C36: FFF1 | D36: A330 | E36: 2152 | F36: 17CE manquant | G36: RWK | H36: 1 | I36: 154.17 | J36: 54.17 | R36: =I36-IF(ISNUMBER(M36),J36-M36*Figures!$C$4,0)+N(N36)*Figures!$C$4+N(O36)+N(P36) -> 154.17
A37: 217037645 | B37: 2026-04-15 | C37: AFM1 | D37: A320 | E37: 13115 | F37: ESAO: GTI: 15XE-A INOP | G37: EXC | H37: 1 | I37: 166.67 | J37: 66.67 | K37: 1029256022 | R37: =I37-IF(ISNUMBER(M37),J37-M37*Figures!$C$4,0)+N(N37)*Figures!$C$4+N(O37)+N(P37) -> 166.67
A38: 217070011 | B38: 2026-04-20 | C38: FFF1 | D38: A330 | E38: 2141 | F38: Contact tordu Borne 20 3667VC | G38: RWK | H38: 1 | I38: 166.67 | J38: 66.67 | K38: 1029291474 | R38: =I38-IF(ISNUMBER(M38),J38-M38*Figures!$C$4,0)+N(N38)*Figures!$C$4+N(O38)+N(P38) -> 166.67
A39: 217143872 | B39: 2026-04-27 | C39: FNZ1 | D39: A350 | E39: 816 | F39: CKPT*C8/9*L21/22*D&G*Etiquette mqte*FB* | G39: ACC | H39: 1 | I39: 100 | J39: 0 | R39: =I39-IF(ISNUMBER(M39),J39-M39*Figures!$C$4,0)+N(N39)*Figures!$C$4+N(O39)+N(P39) -> 100
A40: 217171047 | B40: 2026-04-29 | C40: FFF1 | D40: A330 | E40: 2158 | F40: Equipement 314VU VT mal positionnée | G40: RWK | H40: 1 | I40: 150 | J40: 50 | R40: =I40-IF(ISNUMBER(M40),J40-M40*Figures!$C$4,0)+N(N40)*Figures!$C$4+N(O40)+N(P40) -> 150
A41: 217171214 | B41: 2026-04-29 | C41: FFF1 | D41: A330 | E41: 2158 | F41: Equipement 313VU VT mal positionnée | G41: RWK | H41: 2 | I41: 150 | J41: 50 | K41: 1029489899 | R41: =I41-IF(ISNUMBER(M41),J41-M41*Figures!$C$4,0)+N(N41)*Figures!$C$4+N(O41)+N(P41) -> 150
A42: 217253630 | B42: 2026-05-11 | C42: FNZ1 | D42: A350 | E42: 820 | F42: Backshell manquant | G42: RWK | H42: 1 | I42: 154.17 | J42: 54.17 | K42: 1029573005 | R42: =I42-IF(ISNUMBER(M42),J42-M42*Figures!$C$4,0)+N(N42)*Figures!$C$4+N(O42)+N(P42) -> 154.17
...

Sheet H4_CableCutting
A1: H4. BF24 / BF20 cables cut for stock on rework orders (A330 print room, September 2026)
A2: 37 S03 orders on work centre 4FEM0E14 asking for bundles of 50 cables. The PTVU line had raised disruptions about BF24 quantities in Elec ABC and missing BF24 cables.
A4: Question: is this a consequence of non-quality (cables remade or replaced because of defects) or a definition / kitting problem (cut lists not giving the line the right cables)? Who to ask: methods (Elec ABC quantities), the A330 print room, the PTVU line leader. The related disruptions and NCs are listed further down.
A6: Order | B6: Confirmed | C6: MSN | D6: Planned h | E6: Request | F6: Comment
A7: 1030956049 | B7: 2026-09-09 | C7: 2169 | D7: 3.42 | E7: Débiter câbles BF24 et BF20 Débiter câbles BF24 et BF20 Veuillez débiter du BF24 50 câbles de 100cm Veuillez débiter du BF24 50 câbles de 80cm Veuillez débiter du BF20 50 câbles de 80cm
A8: 1030956972 | B8: 2026-09-09 | C8: 2169 | D8: 3.42 | E8: Débiter câbles BF24 et BF20 Débiter câbles BF24 et BF20 Veuillez débiter du BF24 50 câbles de 100cm Veuillez débiter du BF24 50 câbles de 80cm Veuillez débiter du BF20 50 câbles de 80cm
A9: 1030957008 | B9: 2026-09-09 | C9: 2169 | D9: 3.42 | E9: Débiter câbles BF24 et BF20 Débiter câbles BF24 et BF20 Veuillez débiter du BF24 50 câbles de 100cm Veuillez débiter du BF24 50 câbles de 80cm Veuillez débiter du BF20 50 câbles de 80cm
A10: 1030957018 | B10: 2026-09-09 | C10: 2169 | D10: 3.42 | E10: Débiter câbles BF24 et BF20 Débiter câbles BF24 et BF20 Veuillez débiter du BF24 50 câbles de 100cm Veuillez débiter du BF24 50 câbles de 80cm Veuillez débiter du BF20 50 câbles de 80cm
A11: 1030957042 | B11: 2026-09-09 | C11: 2169 | D11: 3.42 | E11: Débiter câbles BF24 et BF20 Débiter câbles BF24 et BF20 Veuillez débiter du BF24 50 câbles de 100cm Veuillez débiter du BF24 50 câbles de 80cm Veuillez débiter du BF20 50 câbles de 80cm
A12: 1030957054 | B12: 2026-09-09 | C12: 2169 | D12: 3.42 | E12: Débiter câbles BF24 et BF20 Débiter câbles BF24 et BF20 Veuillez débiter du BF24 50 câbles de 100cm Veuillez débiter du BF24 50 câbles de 80cm Veuillez débiter du BF20 50 câbles de 80cm
A13: 1030957059 | B13: 2026-09-09 | C13: 2169 | D13: 3.42 | E13: Débiter câbles BF24 et BF20 Débiter câbles BF24 et BF20 Veuillez débiter du BF24 50 câbles de 100cm Veuillez débiter du BF24 50 câbles de 80cm Veuillez débiter du BF20 50 câbles de 80cm
A14: 1030957073 | B14: 2026-09-09 | C14: 2169 | D14: 3.42 | E14: Débiter câbles BF24 et BF20 Débiter câbles BF24 et BF20 Veuillez débiter du BF24 50 câbles de 100cm Veuillez débiter du BF24 50 câbles de 80cm Veuillez débiter du BF20 50 câbles de 80cm
A15: 1030957083 | B15: 2026-09-09 | C15: 2169 | D15: 3.42 | E15: Débiter câbles BF24 et BF20 Débiter câbles BF24 et BF20 Veuillez débiter du BF24 50 câbles de 100cm Veuillez débiter du BF24 50 câbles de 80cm Veuillez débiter du BF20 50 câbles de 80cm
A16: 1031059358 | B16: 2026-09-17 | C16: 2170 | D16: 1.16 | E16: Débiter câbles BF24 Débiter câbles BF24 Veuillez débiter du BF24 50 câbles de 80cm
A17: 1031059254 | B17: 2026-09-17 | C17: 2170 | D17: 1.16 | E17: Débiter câbles BF24 Débiter câbles BF24 Veuillez débiter du BF24 50 câbles de 80cm
A18: 1031059144 | B18: 2026-09-17 | C18: 2170 | D18: 1.16 | E18: Débiter câbles BF24 Débiter câbles BF24 Veuillez débiter du BF24 50 câbles de 80cm
... A43: 1031244826 | B43: 2026-09-30 | C43: 2173 | D43: 1.16 | E43: Débiter câbles BF24 Débiter câbles BF24 Veuillez débiter du BF24 50 câbles de 100cm
A44: Total planned h | D44: =SUM(D7:D43) -> 77.56
A46: Related disruptions (mention BF24 / BF20)
A47: Disruption | B47: Opened | C47: Line | D47: Time lost (min) | E47: What the operator wrote | F47: Kind
A48: OZ2037505 | B48: 2026-05-29 | C48: IMPRESSION_A380 | D48: 90 | E48: OF 57564460 RECHANGE : il est demandé des manchons sur SOI mais pas de câble à débiter...des câbles BF24 et BF18 apparaissent sur Fiche suiveuse.Doit on livrer que les manchons ? | F48: SUPTECH - Probleme OF-OT et Definition
A49: OZ2099671 | B49: 2026-06-30 | C49: PTVU | D49: 14 | E49: dans elec abc l'onglet qté de type/jauge, pour la VT il est demandé de sertir 64 câbles de bf24 avec en3155-016m2018 alors qu'en comptant à partir de chaque modules il en faut seulement 13 | F49: SUPTECH - Probleme OF-OT et Definition
A50: OZ2146779 | B50: 2026-08-13 | C50: PTVU | D50: 14 | E50: Sur Elec ABC, dans le menu "Quantité de type/jauge (élément d'extrémité)", il y a marqué 22 câbles en BF24 contact 16M2018 mais il n'y a en réalité que 12 câbles à sertir avec ces contacts et les autres doivent être sertis avec les contacts 16M2222 | F50: SUPTECH - Probleme OF-OT et Definition
A51: OZ2170456 | B51: 2026-08-27 | C51: PTVU | D51: 14 | E51: Pièce manquante Bonjour, afin de répondre aux besoins de la production, nous sollicitons la fourniture de câbles BF24 d'une longueur de 80 cm. Merci de vous référer au courriel envoyé par Rachid A. | F51: LOG - Probleme servitude
A52: OZ2188489 | B52: 2026-09-04 | C52: PTVU | D52: 14 | E52: Pièce manquante MQT : Câbles BF24 en 100cm et 80cm. | F52: LOG - Probleme servitude
A53: OZ2243953 | B53: 2026-09-29 | C53: IMPRESSION_A330 | D53: 60 | E53: F955.00412.001.95 OF 57702138 57702341 57702244 57702544 57702549 57701440 Incohérence entre débit cables BF sur Fiche suiveuse et SOI Fiche suiveuse BF 24 L=80cm 29 PCES SUR SOI : 31 câbles de 75cm, 4 de 65cm et 1 de 45 cm BF18 L= 80cm 2 PCES SUR SOI : 2 cables de 75cm | F53: SUPTECH - Probleme OF-OT et Definition
A55: Related NCs (2026 NCs mentioning BF24 / BF20)
A56: NC | B56: Created | C56: Programme | D56: Type | E56: What was found | F56: Long text (extract)
A57: 216074163 | B57: 2026-01-08 | C57: A330 | D57: TEST | E57: 2148 | F57: 14/AIRBUS OPERATIONS SAS ) Tél. 33607657447 NonConformity 0001 : Type of nonconformity : Connection * Def 1-T01 : Câble BF24 N° : 2351-0459 manquant entre 19RN 1 ET 18RN 2. Def 2-T01 : Câble BF24 N° : 2351-0458 manquant entre 19RN 2 ET 18RN 1. Merci
A58: 216111281 | B58: 2026-01-13 | C58: A330 | D58: TEST | E58: Retouche Test 612VU MSN 02148 | F58: 14/AIRBUS OPERATIONS SAS ) Tél. 33607657447 NonConformity 0001 : Type of nonconformity : Connection * Def 1-T01 : Câble BF 24 N° : 2351-0303 manquant entre 15RN 1 et 16RN 2. Def 2-T01 : Câble BF 24 N° : 2351-0302 manquant entre 15RN 2 et 16RN 1. Merc
A59: 216195310 | B59: 2026-01-21 | C59: A330 | D59: TEST | E59: Retouche Test 313VU MSN 02145. | F59: 607657447 NonConformity 0001 : Type of nonconformity : Connection * Def 1-T01 : 4 Câbles manquants en 261VT 1 : - Câble BF24 N°:3163-0918 manquant entre 261VT 1 A et 54FP1 A B1. - Câble BF24 N°:3163-0919 manquant entre 261VT 1 B et 54FP1 A A1. - Câbl
A60: 216195654 | B60: 2026-01-21 | C60: A330 | D60: TEST | E60: Retouche Test 31'VU MSN 02145. | F60: 607657447 NonConformity 0001 : Type of nonconformity : Connection * Def 1-T01 : 3 Câbles manquants en 260VT 1 : - Câble BF 24 N° : 3163-0924 Manquant entre 260VT 1 A et 54FP2 A B1. - Câble BF 24 N° : 3163-0925 Manquant entre 260VT 1 B et 54FP2 A A1.
A61: 216851910 | B61: 2026-03-26 | C61: A330 | D61: TEST | E61: Retouche Test 417VU MSN 02158. | F61: 14/AIRBUS OPERATIONS SAS ) Tél. 33607657447 NonConformity 0001 : Type of nonconformity : Connection * Def 1-T02 : Câble BF24 N° : 3163-0588 branché en 1WS A 7 au lieu de 8WK1 A 7. Merci de remettre le VU en conformité. -- -- -- -- -- -- -- -- -- -- -
A62: 217019027 | B62: 2026-04-14 | C62: A330 | D62: TEST | E62: Retouche Test 245VU MSN 02157. | F62: OPERATIONS SAS ) Tél. 33607657447 NonConformity 0001 : Type of nonconformity : Fault in continuity * Def 1-T03 : Shunt BF24 N° : 3314-0919 Manquant entre 651VT3 C et 651VT5 R. Merci de remettre le VU en conformité. -- -- -- -- -- -- -- -- -- -- -- --
A63: 217055268 | B63: 2026-04-17 | C63: A330 | D63: TEST | E63: Retouche Test 616VU MSN 02157. | F63: OPERATIONS SAS ) Tél. 33607657447 NonConformity 0001 : Type of nonconformity : Fault in continuity * Def 1-T01 : Câble BF24 N° : 2351-0458 Manquant entre 18RN 1 et 19RN 2. Def 2-T01 : Câble BF24 N° : 2351-0459 Manquant entre 18RN 2 et 19RN 1. Câbles
A64: 217140319 | B64: 2026-04-27 | C64: A330 | D64: QUALITE | E64: Cables manquants suite NC 217055268 | F64: ng Part/Component / Incomplete Kit * Suite à la NC 217055268 , il a été détecté lors du test deux câbles manquant. * 1- BF24 N° 2351-0458 entre 18RN 1 et 19RN 2 2- BF24 N° 2351-0459 entre 18RN 2 et 19RN 1 * Merci de commander ces câbles pour effectue
A65: 217451299 | B65: 2026-06-03 | C65: A330 | D65: TEST | E65: Retouches Test 245VU MSN 02160. | F65: nconformity : Connection * Def 1-Q06 : Le Câblage en 653VT 7 a été effectué avec le MSN 02159 au lieu de 02160. - Câble BF24 N° : 3314-1130 branché entre 653VT 7L et 650VC BB à déposer. Def 2-Q06 : Le Câblage en 653VT 7 a été effectué avec le MSN 021

Sheet H5_NCsNoOrder
A1: H5. Reworked NCs with no rework order
A2: Decision 'rework', FTO2 liable, raised at FTO2, but no rework order in the NC's linked_document (an AW_/WO_/RS_ number different from its own work order).
A4: 96-97% of reworked NCs get their own rework order. For these few, check in SAP whether the rework was done on the spot (no order needed) or whether an order exists but was never linked to the NC. If orders exist unlinked, the 'rework order' rule misses them.
A6: NC | B6: Year | C6: Created | D6: NC type | E6: Workflow | F6: Station | G6: Written by | H6: What was found | I6: linked_document | J6: Own work order | K6: Fixed on the spot? (Y/N) | L6: Order exists but link missing? (Y/N) | M6: Comment
A7: 218413734 | B7: 2026 | C7: 2026-09-28 | D7: NC Interne | E7: REW-LIGNE-V | F7: V4QMI2 | G7: QRT/DERICHEBOURG AERONAUTICS | H7: Retouches finales | J7: 001030718127
A8: 218409412 | B8: 2026 | C8: 2026-09-28 | D8: TEST | E8: TEST-RET | F8: V42RA1 | G8: OLMEP14/AIRBUS OPERATIONS SAS | H8: RETOUCHES TEST MSN0870. | J8: 001030163689
A9: 218320671 | B9: 2026 | C9: 2026-09-18 | D9: NC Interne | E9: REW-LIGNE-D | F9: D42D01 | G9: QR/DERICHEBOURG AERONAUTICS | H9: Prises 10LB-A et 7588VC-A non torquées | J9: 001030822062
A10: 218315000 | B10: 2026 | C10: 2026-09-17 | D10: CABLES | E10: REW-CA-IMP-V | F10: V4V120 | G10: QRT/DERICHEBOURG AERONAUTICS | H10: Câble trop court | J10: 001030811458
A11: 218208196 | B11: 2026 | C11: 2026-09-08 | D11: CONTROLE FINAL | E11: REW-LIGNE-V | F11: V4V214 | G11: QLOT1/AIRBUS OPERATIONS SAS | H11: Aléa OZ2193509 Prise abimée EN3645-M6CN9 | J11: 001030355794
A12: 218105386 | B12: 2026 | C12: 2026-08-27 | D12: CONTROLE FINAL | E12: REW-LIGNE-F | F12: F4F012 | G12: QLOT1/AIRBUS OPERATIONS SAS | H12: FOURREAU MONTE A L'ENVERS | J12: 001030172079
A13: 218069982 | B13: 2026 | C13: 2026-08-24 | D13: TEST | E13: REW-TEST-F | F13: F4F015 | G13: OLMEP14/AIRBUS OPERATIONS SAS | H13: SHUNTS MANQUANTS | J13: 001030067999
A14: 218005905 | B14: 2026 | C14: 2026-08-14 | D14: NC Interne | F14: V4V142 | G14: QR/DERICHEBOURG AERONAUTICS | H14: FOd contact femelle : MIP 858 | J14: 001029493692
A15: 217530835 | B15: 2026 | C15: 2026-06-11 | D15: TEST | E15: REW-TEST-V | F15: V42RA1 | G15: OLMEP14/AIRBUS OPERATIONS SAS | H15: RETOUCHE TEST MSN 853 CONTACT A REFAIRE | J15: 001029148565
A16: 217407744 | B16: 2026 | C16: 2026-05-29 | D16: DEMANDE DE DQN | E16: LIGNE-F-DQN | F16: M4MMIC | G16: QLOT1/AIRBUS OPERATIONS SAS | H16: Excessive shunt length on 8RZA connector | J16: 001029267550
A17: 217328612 | B17: 2026 | C17: 2026-05-20 | D17: NC Interne | E17: REW-LIGNE-D | F17: D42D01 | G17: QR/DERICHEBOURG AERONAUTICS | H17: Harnais 452VB court | J17: 001029405757
A18: 217230702 | B18: 2026 | C18: 2026-05-07 | D18: CABLES | E18: REW-CA-IMP-F | F18: F4F74C | G18: QLOT1/AIRBUS OPERATIONS SAS | H18: CABLE MANQUANT | J18: 001029148720
A19: 216820892 | B19: 2026 | C19: 2026-03-24 | D19: CONTROLE FINAL | E19: REW-LIGNE-M | F19: M4M30C | G19: QLOT1/AIRBUS OPERATIONS SAS | H19: 3 détrompeurs montés fabriqués par ATM | J19: 001027381521
A20: 216801004 | B20: 2026 | C20: 2026-03-23 | D20: NC Interne | E20: REW-LIGNE-D | F20: D42D01 | G20: QR/DERICHEBOURG AERONAUTICS | H20: Harnais 452VB court | J20: 001028634452
A21: 216764494 | B21: 2026 | C21: 2026-03-18 | D21: CONTROLE FINAL | E21: REW-LIGNE-D | F21: D42F14 | G21: QLOT1/AIRBUS OPERATIONS SAS | H21: Pince à sertir non conforme | J21: 001027973023
A22: 216699966 | B22: 2026 | C22: 2026-03-12 | D22: NC Interne | E22: REW-LIGNE-V | F22: V4V141 | G22: QRT/DERICHEBOURG AERONAUTICS | H22: Contrôle final qualité après test | J22: 001027848168
A23: 216381151 | B23: 2026 | C23: 2026-02-09 | D23: CONTROLE FINAL | E23: REW-LIGNE-M | F23: M4M30C | G23: QLOK310/AIRBUS OPERATIONS SAS | H23: Trous ovalisés hors tolérence | J23: 001026799692
A24: 213554463 | B24: 2025 | C24: 2025-02-18 | D24: NC Interne | E24: REW-LIG-ST-V | F24: V4V120 | G24: OLMEP1/ERMA ELECTRONIQUE | H24: Câble AD24 2797-1126 court
A25: 213618542 | B25: 2025 | C25: 2025-02-26 | D25: CONTROLE FINAL | E25: REW-LIGNE-F | F25: F4F74G | G25: QLOK310/AIRBUS OPERATIONS SAS | H25: impossibilité d'appliquer torquage | J25: 1023914810
A26: 213510668 | B26: 2025 | C26: 2025-02-12 | D26: NC Interne | E26: LIGNE-DQN | F26: V4V115 | G26: QRT/DERICHEBOURG AERONAUTICS | H26: Support lacote petit routes 1S et 2S | J26: 1023996325
A27: 215109338 | B27: 2025 | C27: 2025-09-18 | D27: CONTROLE FINAL | E27: REW-LIGNE-F | F27: F4F015 | G27: QLOK310/AIRBUS OPERATIONS SAS | H27: S/N TEMP SELECTOR non conforme | I27: [TS_000000001019419485] | J27: 1025848561
A28: 215451241 | B28: 2025 | C28: 2025-10-23 | D28: NC Interne | E28: REC-RWK | F28: F42RC1 | G28: QR/DERICHEBOURG AERONAUTICS | H28: CPB NOK | J28: 1026915093
A29: 215030360 | B29: 2025 | C29: 2025-09-10 | D29: CONTROLE FINAL | E29: REW-LIGNE-M | F29: M4MOHF | G29: QLOT1/AIRBUS OPERATIONS SAS | H29: impossibilité d'appliquer torquage rampe | J29: 1025486392
A30: 215372645 | B30: 2025 | C30: 2025-10-15 | D30: NC Interne | E30: REW-LIGNE-F | F30: F4F74E | G30: QR/DERICHEBOURG AERONAUTICS | H30: ERREUR MONTAGE DECOUPLING UNIT | J30: 1026113365
A31: 214388588 | B31: 2025 | C31: 2025-06-11 | D31: CONTROLE FINAL | E31: REW-LIGNE-F | F31: F4F034 | G31: QLOT1/AIRBUS OPERATIONS SAS | H31: Vis endommagée sur fourreau | J31: 1025196094
A32: 213884687 | B32: 2025 | C32: 2025-04-01 | D32: CABLES | E32: REW-CA-IMP-V | F32: V4V120 | G32: QLOT1/AIRBUS OPERATIONS SAS | H32: cable trop court | J32: 1024388395
A33: 215191868 | B33: 2025 | C33: 2025-09-26 | D33: CONTROLE FINAL | E33: REW-LIGNE-F | F33: F4F012 | G33: QLOK310/AIRBUS OPERATIONS SAS | H33: TEMP.SELECTOR avec deux CT176 | I33: [TS_000000001020577721] | J33: 1026106139
A34: 213973964 | B34: 2025 | C34: 2025-04-11 | D34: CABLES | E34: REW-CA-IMP-F | F34: F4F74A | G34: QLOT1/AIRBUS OPERATIONS SAS | H34: CABLE MANQUANT | J34: 1024517181
A35: 213666329 | B35: 2025 | C35: 2025-03-04 | D35: CABLES | E35: REW-CA-IMP-V | F35: V4V120 | G35: QLOT1/AIRBUS OPERATIONS SAS | H35: câble endommagé | J35: 1023833666
A36: 213559949 | B36: 2025 | C36: 2025-02-19 | D36: CABLES | E36: REW-CA-IMP-V | F36: V42RA1 | G36: QLOT1/AIRBUS OPERATIONS SAS | H36: Cable manquant
A37: 214352478 | B37: 2025 | C37: 2025-06-05 | D37: CONTROLE FINAL | E37: REW-LIGNE-F | F37: F4F038 | G37: QLOT1/AIRBUS OPERATIONS SAS | H37: Vis du fourreau 5WW2 endommagées | J37: 1025084201
A38: 215620253 | B38: 2025 | C38: 2025-11-10 | D38: CONTROLE FINAL | E38: REW-LIGNE-V | F38: V4V141 | G38: QLOT1/AIRBUS OPERATIONS SAS | H38: NC en attente réponse BE (DQN) | J38: 1026370581
A39: 213655218 | B39: 2025 | C39: 2025-03-03 | D39: CABLES | E39: REW-CA-IMP-V | F39: V42110 | G39: QRT/DERICHEBOURG AERONAUTICS | H39: Câble trop court et Abimé
A40: 213628687 | B40: 2025 | C40: 2025-02-27 | D40: NC Interne | E40: REW-LIG-ST-V | F40: V42120 | G40: OLMEP1/ERMA ELECTRONIQUE | H40: Cable 2792-0994 abîmé
A41: 215500224 | B41: 2025 | C41: 2025-10-28 | D41: NC Interne | E41: REGROUP-DQN | F41: M4M30C | G41: QLOT1/AIRBUS OPERATIONS SAS | H41: TORQUAGE BARRETTE 315VT | I41: [TS_000000001020387999] | J41: 1026099937
A42: 214750407 | B42: 2025 | C42: 2025-07-23 | D42: CONTROLE FINAL | E42: REW-LIGNE-V | F42: V42120 | G42: QLOT1/AIRBUS OPERATIONS SAS | H42: Mauvaise servitude de contact | J42: 1025774755
...

Sheet H6_OrdersNoTime
A1: H6. Rework orders with no planned time (September 2026)
A2: S03 rework orders whose operations carry no standard value. If planned time is the truth, these orders cost 0, which cannot be right.
A4: Questions: why do these orders have no standard value (operations created without time, closed without confirmation, time booked elsewhere)? Until known, the CNQ uses the model's estimate for NCs whose order has no planned time. 63 of the 249 shop-floor rework orders (25%) are in this case.
A6: Rework order | B6: Family | C6: Programme | D6: MSN | E6: Linked NC | F6: NC type | G6: NC: what was found | H6: Work centre(s) | I6: Operations | J6: Why no time? (your finding) | K6: Comment
A7: 1030448899 | B7: FTO2 shop floor | C7: A330 | D7: 2169 | E7: 217899785 | F7: CABLES | G7: CABLES MANQUANTS | H7: Attestation de conformitÃ© / Inspection fabrication elec | I7: Attestation de conformité || Inspection Qualité
A8: 1030475889 | B8: FTO2 shop floor | C8: A330 | D8: 2166 | E8: 217913295 | F8: NC Interne | G8: INVERSEUR H.S. | H8: Attestation de conformitÃ© / Inspection fabrication elec | I8: Attestation de conformité || Inspection Qualité
A9: 1030621326 | B9: FTO2 shop floor | C9: A330 | D9: 2166 | E9: 218016079 | F9: TEST | G9: CABLES A CHANGER | H9: Attestation de conformitÃ© / Inspection fabrication elec | I9: Attestation de conformité || Inspection Qualité
A10: 1030623390 | B10: FTO2 shop floor | C10: A350 | D10: 870 | E10: 218020323 | F10: CABLES | G10: Câbles trop courts | H10: Attestation de conformitÃ© / Inspection fabrication elec | I10: Attestation de conformité || Inspection Qualité
A11: 1030721063 | B11: FTO2 shop floor | C11: A330 | D11: 2167 | E11: 218067875 | F11: CONTROLE FINAL | G11: RETOUCHE CONTROLE FINAL | H11: Attestation de conformitÃ© / Inspection fabrication elec | I11: Attestation de conformité || Inspection Qualité
A12: 1030721069 | B12: FTO2 shop floor | C12: A330 | D12: 2167 | E12: 218067687 | F12: CONTROLE FINAL | G12: RETOUCHE CONTROLE FINAL | H12: Attestation de conformitÃ© / Inspection fabrication elec | I12: Attestation de conformité || Inspection Qualité
A13: 1030721510 | B13: FTO2 shop floor | C13: A330 | D13: 2167 | E13: 218070160 | F13: TEST | G13: INTERDIT CASSE | H13: Attestation de conformitÃ© / Inspection fabrication elec | I13: Attestation de conformité || Inspection Qualité
A14: 1030736570 | B14: FTO2 shop floor | C14: A350 | D14: 868 | E14: 218078858 | F14: CABLES | G14: Câble KL coupé trop court | H14: Attestation de conformitÃ© / Inspection fabrication elec | I14: Attestation de conformité || Inspection Qualité
A15: 1030740403 | B15: FTO2 shop floor | C15: A330 | D15: 2167 | H15: Attestation de conformitÃ© / Inspection fabrication elec | I15: Attestation de conformité || Inspection Qualité
A16: 1030763128 | B16: FTO2 shop floor | C16: A350 | D16: 868 | E16: 218094742 | F16: CABLES | G16: Mauuvaise MOE serre module NSA937901S | H16: Attestation de conformitÃ© / Inspection fabrication elec | I16: INSPECTION QUALITE || ATTESTATION DE CONFORMITE ATTESTATION DE CONFORMITE Inspection avant la clôture de l'OF
A17: 1030781941 | B17: FTO2 shop floor | C17: A350 | D17: 872 | E17: 218113625 | F17: CABLES | G17: Câble trop court | H17: Attestation de conformitÃ© / Inspection fabrication elec | I17: Attestation de conformité || Inspection Qualité
A18: 1030818117 | B18: FTO2 shop floor | C18: A350 | D18: 856 | E18: 218121468 | F18: NC Retour client | G18: CKPT*C1*L22/23*G*Gaine écrasée*BA@* | H18: Attestation de conformitÃ© / Inspection fabrication elec | I18: Attestation de conformité || Contrôle du KIT(s) avant le départ pour Contrôle du KIT(s) avant le départ pour Montoir-de-Bretagne Suite à la NC 218121468, veuillez contrôler la conformité du kit avant le départ pour Montoir-de-Bretagne suivant la list
A19: 1030818179 | B19: FTO2 shop floor | C19: A350 | D19: 856 | E19: 218121463 | F19: NC Retour client | G19: CKPT*C1*L22/21*D*Gaine écrasée*BA@* | H19: Attestation de conformitÃ© / Inspection fabrication elec | I19: Attestation de conformité || Contrôle du KIT(s) avant le départ pour Contrôle du KIT(s) avant le départ pour Montoir-de-Bretagne Suite à la NC 218121463, veuillez contrôler la conformité du kit avant le départ pour Montoir-de-Bretagne suivant la list
A20: 1030938126 | B20: FTO2 shop floor | C20: A350 | D20: 865 | E20: 218213110 | F20: TEST | G20: RETOUCHE TEST PRISE DETERIORE | H20: A350-REC-S/T-Attestation Conformité / Basic Electrical harness manufacturing / Réaliser Inspection | I20: Attestation de conformité Attestation de conformité Inspection avant la clôture de l'OF || Inspection Qualité || Remise en conformités de la prise 20TC1 Remise en conformités de la prise 20TC1 A Veuillez Appliquer la NSI joint à la S03.
A21: 1030985640 | B21: FTO2 shop floor | C21: A350 | D21: 866 | E21: 218242503 | F21: TEST | G21: RETOUCHE TEST MSN 866 TWINAX A REFAIRE | H21: A350-REC-S/T-Attestation Conformité / Basic Electrical harness manufacturing / Réaliser Inspection | I21: Attestation de conformité || Inspéction Qualité Inspéction Qualité NC CABLE - Inspection Qualité SI NC TA --> 4QEH1I07 NC TEST - Inspection Qualité --> 4QEH5I07 NC QUALITÉ - Inspection Qualité --> 4QEH8I07 NC CABLE - Inspection Qualité SI NC TB --> 4
A22: 1030986429 | B22: FTO2 shop floor | C22: A350 | D22: 876 | E22: 218246376 | F22: CABLES | G22: Câbles non lasérisés | H22: A350-REC-S/T-Attestation Conformité / Basic Electrical harness manufacturing | I22: Attestation de conformité || PRELEVEMENT MSN 878 VERS MSN 876 PRELEVEMENT MSN 878 VERS MSN 876 S03 suite à la NC 218246376 : Prélèvement des câbles du MSN 878 vers le MSN 876 sous ISOCONF identique (Accord BP)
A23: 1030989646 | B23: FTO2 shop floor | C23: A350 | D23: 858 | E23: 218221555 | F23: NC Retour client | G23: ATT*FB*C6*L25*D*Mauvais backshell *LA@* | H23: Attestation de conformitÃ© / Inspection fabrication elec | I23: Contrôle du KIT(s) avant le départ pour Contrôle du KIT(s) avant le départ pour Montoir-de-Bretagne Suite à la NC 218221555, veuillez contrôler la conformité du kit avant le départ pour Montoir-de-Bretagne suivant la liste ci-dessous : Désignation /
A24: 1031170705 | B24: FTO2 shop floor | C24: A350 | D24: 728 | E24: 218348034 | F24: NC Retour client | G24: CKPT*C7/8*L24/25*D*Mauvais Backshell*FB* | H24: Attestation de conformitÃ© / Inspection fabrication elec | I24: Attestation de conformité || Contrôle du KIT(s) avant le départ pour Contrôle du KIT(s) avant le départ pour Montoir-de-Bretagne Suite à la NC 218348034, veuillez contrôler la conformité du kit avant le départ pour Montoir-de-Bretagne suivant la list
A25: 1031171305 | B25: FTO2 shop floor | C25: A350 | D25: 856 | E25: 218348243 | F25: NC Retour client | G25: CKPT*C7/8*L24/25*D*Mauvais Backshell*FB* | H25: Attestation de conformitÃ© / Inspection fabrication elec | I25: Contrôle du KIT(s) avant le départ pour Contrôle du KIT(s) avant le départ pour Montoir-de-Bretagne Suite à la NC 218348243, veuillez contrôler la conformité du kit avant le départ pour Montoir-de-Bretagne suivant la liste ci-dessous : Désignation /
A26: 1031220048 | B26: FTO2 shop floor | C26: A350 | D26: 857 | E26: 218390076 | F26: NC Retour client | G26: CKPT*C7/8*L24/25*D*Mauvais Backshell*FB* | H26: Attestation de conformitÃ© / Inspection fabrication elec | I26: Attestation de conformité || Contrôle du KIT(s) avant le départ pour Contrôle du KIT(s) avant le départ pour Montoir-de-Bretagne Suite à la NC 218390076, veuillez contrôler la conformité du kit avant le départ pour Montoir-de-Bretagne suivant la list
A27: 1031227280 | B27: FTO2 shop floor | C27: A350 | D27: 858 | E27: 218390072 | F27: NC Retour client | G27: CKPT*C7/8*D&G*Mauvais Backshell*FB* | H27: Attestation de conformitÃ© / Inspection fabrication elec | I27: Contrôle du KIT(s) avant le départ pour Contrôle du KIT(s) avant le départ pour Montoir-de-Bretagne Suite à la NC 218390072, veuillez contrôler la conformité du kit avant le départ pour Montoir-de-Bretagne suivant la liste ci-dessous : Désignation /
... A29: 1031227573 | B29: FTO2 shop floor | C29: A350 | D29: 861 | E29: 218390345 | F29: NC Retour client | G29: CKPT*C7/8*D&G*Mauvais Backshell*FB* | H29: Attestation de conformitÃ© / Inspection fabrication elec | I29: Contrôle du KIT(s) avant le départ pour Contrôle du KIT(s) avant le départ pour Montoir-de-Bretagne Suite à la NC 218390345, veuillez contrôler la conformité du kit avant le départ pour Montoir-de-Bretagne suivant la liste ci-dessous : Désignation /
A30: 1029645893 | B30: FTO2 shop floor | C30: A350 | D30: 701 | H30: Attestation Conformité / Basique fabrication Electrique / Inspection qualité | I30: ATTESTATION DE CONFORMITE || CONTROLE CONTROLE Cet OT est en // de l'OF 1028559128 (FB37531) || Veuillez installer les documents A3 plas Veuillez installer les documents A3 plastifié sur les portes avants, près du trailing cone et près dy FTES avec d
A31: 1030618214 | B31: FTO2 shop floor | C31: A350 | D31: 867 | H31: A350-REC-S/T-Attestation Conformité | I31: Attestation de conformité
A32: 1030699591 | B32: FTO2 shop floor | C32: A350 | D32: 870 | H32: A350-REC-S/T-Attestation Conformité / Basic Electrical harness manufacturing / Réaliser Inspection | I32: Attestation de conformité || Inspection Qualité || ONTROLER SERTISSAGE CDVE tête A || Remise en conformités du câble Remise en conformités du câble Cheminer le câble vers la tête B. S'appuyer des informations décrites suivant la définition sur ElecAB
A33: 1030754959 | B33: FTO2 shop floor | C33: A350 | D33: 865 | H33: A350-REC-S/T-Attestation Conformité | I33: Attestation de conformité
A34: 1030755222 | B34: FTO2 shop floor | C34: A350 | D34: 871 | H34: A350-REC-S/T-Attestation Conformité / Basic Electrical harness manufacturing / Réaliser Inspection | I34: Attestation de conformité || Inspection Qualité || NC CABLE - Remise en conformités du câbl NC CABLE - Remise en conformités du câble Effectuer le dénudage / sertissage du câble en tête A suivant les informations de la définition sur ElecABC/NIICE. E
A35: 1030780734 | B35: FTO2 shop floor | C35: A350 | D35: 872 | H35: A350-REC-S/T-Attestation Conformité / Réaliser Inspection | I35: Attestation de conformité || Inspection Qualité || CONTROLER SERTISSAGE CDVE
A36: 1030780933 | B36: FTO2 shop floor | C36: A350 | D36: 700 | H36: ATTESTATION DE CONFORMITE S/T / Attestation Conformité / Fabrication Harnais Electrique | I36: Attestation de conformité || Intallation support supplémentaires : Intallation support supplémentaires : Localisation: Cadre 72 AFT-US - Cadre-77-AFT-US. Latch Top AFT, Button AFT, TOP FWD et Button FWD. Montez le NSA935405-01 sur la poutre de verrou
A37: 1030791966 | B37: FTO2 shop floor | C37: A330 | D37: 2166 | H37: Attestation de conformitÃ© / Contrôle impression | I37: Inspection Qualité || Attestation de conformité
A38: 1030793434 | B38: FTO2 shop floor | C38: A350 | D38: 700 | H38: ATTESTATION DE CONFORMITE S/T / Attestation Conformité / Fabrication Harnais Electrique | I38: Attestation de conformité || CONTROLER || Remise en conformité. || Analyse de dossier : Analyse de dossier : Localisation : cadres 57/58 et 31/32 coté droit. Merci de refaire le routing au scotch alu sur les Linings en MD.
A39: 1030804587 | B39: FTO2 shop floor | C39: A350 | D39: 868 | H39: A350-REC-S/T-Attestation Conformité / Basic Electrical harness manufacturing / Réaliser Inspection | I39: Attestation de conformité || Inspection Qualité || Remise en conformités du câble Remise en conformités du câble Effectuer le sertissage du câble en tête A et tête B suivant les informations de la définition sur ElecABC/NIICE. Effectuer le branchemen
A40: 1030807762 | B40: FTO2 shop floor | C40: A320 | D40: 6101 | H40: Attestation Conformité / Fabrication Harnais Electrique / Inspection qualité | I40: ATTESTATION DE CONFORMITE || CONTROLER || PREPARATION / ANALYSE DOSSIER || Repose DD253 S/N 25109 et 2511 4ZU Repose DD253 S/N 25109 et 2511 4ZU Veuillez installer les équipements DD253 FIN : 253ZSC2 SN : 25109 ainsi que, FIN : 253ZSC1 SN : 25110 Veu
A41: 1030819680 | B41: FTO2 shop floor | C41: A350 | D41: 701 | H41: Attestation Conformité / Fabrication Harnais Electrique / Inspection qualité | I41: Attestation de conformité || Remise en conformité 743ZVC102-A Remise en conformité 743ZVC102-A Sur la prise 743ZVC102-A Inversion de câblage entre les pin 21,22,23 et 24. Veuillez vous mettre en conformité par rapport au WD V89596412-81. || Contrôle
... A85: 1030742346 | B85: REC (FAL) | C85: A350 | D85: 836 | H85: ATTESTATION OF CONFORMITY / ATTESTATION OF CONFORMITY AUTOCLOSURE / Inspecter installation électri | I85: Inspection avant la clôture de l'OF || Stop point : Attendre Inter. nettoyage || Attestation de conformité Attestation de conformité Controle des points suivants : Toutes les opérations ont été terminées et certifiées Aucun écart évident, manquant ou

Sheet H7_DisruptExport
A1: H7. Is the disruption export complete? (2,500 rows)
A2: The file has exactly 2,500 rows, sorted newest first: the pattern of an export cut at a row limit.
A4: Rows in the file | B4: 2500
A5: First disruption | B5: 2026-01-05 08:57:14
A6: Last disruption | B6: 2026-09-30 23:31:51
A7: File order | B7: newest first (30 Sep 23:31 on the first row)
A8: NCs created 29 Dec 2025 - 2 Jan 2026 (plant closed?) | B8: 0
A9: First NC of 2026 | B9: 5 Jan 2026 (same day as the first disruption)
A10: Usual time of the first disruption of a day | B10: about 07:43
A11: Time of the first disruption on 5 Jan | B11: 08:57 (9 disruptions that day; a usual Monday has about 14)
A13: How to check (any one is enough):
A14: 1. Re-export the disruptions with only 1 Jan - 31 Mar 2026 selected. If 5 January gets more than 9 rows, or rows before 08:57, the first export was cut.
A15: 2. Look in the export tool (Skywise / Contour) for a row limit or a 'first N rows' setting.
A16: 3. Count the disruptions in MES for 5 January 2026 and compare with 9.
A18: Check | B18: Result (your finding) | C18: Export complete? (Y/N)
A19: Re-export Jan-Mar: rows on 5 Jan
A20: Row limit in the export tool
A21: MES count for 5 Jan
A23: Disruptions per day, first two weeks of the file
A24: 2026-01-05 | B24: 9
A25: 2026-01-06 | B25: 26
A26: 2026-01-07 | B26: 14
A27: 2026-01-08 | B27: 18
A28: 2026-01-09 | B28: 10
A29: 2026-01-12 | B29: 28
A30: 2026-01-13 | B30: 19
A31: 2026-01-14 | B31: 38
A32: 2026-01-15 | B32: 18
A33: 2026-01-16 | B33: 5
A35: Time columns: time_lost is typed by the operator (minutes). time_to_get_ack / time_to_get_fix do not match the timestamps (1-2 h time-zone shift; time_to_get_fix is 0 for 64%).

Sheet D_Block
A1: Disruption block (option B): quality aléas that did not lead to an NC
A2: MES disruptions of type 'QLS - Probleme qualite', Jan-Sep 2026, with no NC on the same work order within -2 h..+72 h. Aléas that led to an NC are inside the NC cost (alert step), not here.
A4: Pre-filled Y for every row. Put N for an aléa that should not count (for example, its NC exists but is written by ERMA, which is out of scope). The totals below and in Figures follow.
A6: Disruption | B6: Opened | C6: Month (yyyymm) | D6: Line | E6: Station | F6: Work order | G6: Time lost (min) | H6: What the operator wrote | I6: Answer | J6: Possible ERMA NC (MIP / 1101VB) | K6: Keep in block? (Y/N) | L6: Comment
A7: OZ1780938 | B7: 2026-01-05 08:57 | C7: 202601 | D7: A30 | E7: INTEG2 | F7: 1027044105 | G7: 60 | H7: Impossibilité de monter la Pipe V2511259700000 suite a un montage non conforme fournisseur. | K7: Y
A8: OZ1783404 | B8: 2026-01-06 14:30 | C8: 202601 | D8: MDCD | E8: HARNAIS_MDCD | F8: 1027383554 | G8: 360 | H8: 2 formations réalisé , mesure lineique , recherche de gamme | K8: Y
A9: OZ1785059 | B9: 2026-01-07 12:23 | C9: 202601 | D9: 740VU_743VU | E9: INTE 740VU | F9: 1027341953 | G9: 72 | H9: Changement de deux câbles sur la platine relais temps perdu 2h | K9: Y
A10: OZ1785431 | B10: 2026-01-07 14:47 | C10: 202601 | D10: MDCD | E10: HARNAIS_MDCD | F10: 1027383554 | G10: 330 | H10: Recherche de gamme | K10: Y
