Workbook

Sheet Lisez-moi
A1: Revue du suivi « NC câbles et analyses » — septembre 2026
A2: Base : les 475 lignes du suivi (S02–S40), relues contre le texte des NC SAP quand il est disponible (213 lignes) et contre le commentaire d’analyse du suivi (465 lignes).
A4: Onglets
A5: Revue NC — une ligne par NC à revoir : ce que dit la NC, ce que dit l’analyse, ce qu’on propose.
A6: Convention coupé court — les 98 lignes où le texte dit « coupé (trop) court », pour fixer une règle unique.
A7: Absentes du suivi — reprises de câbles trouvées dans SAP mais pas dans le suivi.
A8: Causes nommées — lignes où l’analyse nomme une cause au-delà de l’état du câble (cheminement, sertissage, machine…).
A9: Hygiène du suivi — doublons, dates, NC supprimées, colonnes vides.
A10: Synthèse — décompte par catégorie (se met à jour avec la Revue NC).
A12: À remplir
A13: Dans « Revue NC », seules les deux colonnes sur fond jaune sont à remplir : « Réponse équipe » (texte libre) et « Décision » (liste : Corrigé / Confirmé tel quel / À discuter).
A14: Niveau : « Erreur probable » = le texte contredit clairement le libellé ; « À confirmer » = contradiction, mais l’analyse a pu trancher autrement ; « Convention à fixer » = même situation, libellés différents.
A16: Exemple de réponse (format attendu)
A17: NC | B17: Motif (suivi) | C17: Proposition | D17: Réponse équipe | E17: Décision
A18: 217544334 | B18: Câble court | C18: Câble manquant | D18: Oui, erreur de saisie : câble jamais livré | E18: Corrigé

Sheet Synthèse
A1: Synthèse de la revue
A3: Catégorie | B3: Erreur probable | C3: À confirmer | D3: Convention à fixer | E3: Total | F3: Traitées
A4: Motif | B4: =COUNTIFS('Revue NC'!$H$2:$H$47,$A4,'Revue NC'!$I$2:$I$47,B$3) -> 11 | C4: =COUNTIFS('Revue NC'!$H$2:$H$47,$A4,'Revue NC'!$I$2:$I$47,C$3) -> 2 | D4: =COUNTIFS('Revue NC'!$H$2:$H$47,$A4,'Revue NC'!$I$2:$I$47,D$3) -> 0 | E4: =SUM(B4:D4) -> 13 | F4: =COUNTIFS('Revue NC'!$H$2:$H$47,$A4,'Revue NC'!$O$2:$O$47,"<>") -> 0
A5: Hors périmètre câble | B5: =COUNTIFS('Revue NC'!$H$2:$H$47,$A5,'Revue NC'!$I$2:$I$47,B$3) -> 1 | C5: =COUNTIFS('Revue NC'!$H$2:$H$47,$A5,'Revue NC'!$I$2:$I$47,C$3) -> 0 | D5: =COUNTIFS('Revue NC'!$H$2:$H$47,$A5,'Revue NC'!$I$2:$I$47,D$3) -> 0 | E5: =SUM(B5:D5) -> 1 | F5: =COUNTIFS('Revue NC'!$H$2:$H$47,$A5,'Revue NC'!$O$2:$O$47,"<>") -> 0
A6: N° de NC | B6: =COUNTIFS('Revue NC'!$H$2:$H$47,$A6,'Revue NC'!$I$2:$I$47,B$3) -> 1 | C6: =COUNTIFS('Revue NC'!$H$2:$H$47,$A6,'Revue NC'!$I$2:$I$47,C$3) -> 0 | D6: =COUNTIFS('Revue NC'!$H$2:$H$47,$A6,'Revue NC'!$I$2:$I$47,D$3) -> 0 | E6: =SUM(B6:D6) -> 1 | F6: =COUNTIFS('Revue NC'!$H$2:$H$47,$A6,'Revue NC'!$O$2:$O$47,"<>") -> 0
A7: Même situation, motifs différents | B7: =COUNTIFS('Revue NC'!$H$2:$H$47,$A7,'Revue NC'!$I$2:$I$47,B$3) -> 0 | C7: =COUNTIFS('Revue NC'!$H$2:$H$47,$A7,'Revue NC'!$I$2:$I$47,C$3) -> 0 | D7: =COUNTIFS('Revue NC'!$H$2:$H$47,$A7,'Revue NC'!$I$2:$I$47,D$3) -> 3 | E7: =SUM(B7:D7) -> 3 | F7: =COUNTIFS('Revue NC'!$H$2:$H$47,$A7,'Revue NC'!$O$2:$O$47,"<>") -> 0
A8: Commentaire ≠ NC | B8: =COUNTIFS('Revue NC'!$H$2:$H$47,$A8,'Revue NC'!$I$2:$I$47,B$3) -> 0 | C8: =COUNTIFS('Revue NC'!$H$2:$H$47,$A8,'Revue NC'!$I$2:$I$47,C$3) -> 3 | D8: =COUNTIFS('Revue NC'!$H$2:$H$47,$A8,'Revue NC'!$I$2:$I$47,D$3) -> 0 | E8: =SUM(B8:D8) -> 3 | F8: =COUNTIFS('Revue NC'!$H$2:$H$47,$A8,'Revue NC'!$O$2:$O$47,"<>") -> 0
A9: Plusieurs défauts, un seul motif | B9: =COUNTIFS('Revue NC'!$H$2:$H$47,$A9,'Revue NC'!$I$2:$I$47,B$3) -> 0 | C9: =COUNTIFS('Revue NC'!$H$2:$H$47,$A9,'Revue NC'!$I$2:$I$47,C$3) -> 2 | D9: =COUNTIFS('Revue NC'!$H$2:$H$47,$A9,'Revue NC'!$I$2:$I$47,D$3) -> 0 | E9: =SUM(B9:D9) -> 2 | F9: =COUNTIFS('Revue NC'!$H$2:$H$47,$A9,'Revue NC'!$O$2:$O$47,"<>") -> 0
A10: Plusieurs défauts, une seule imputation | B10: =COUNTIFS('Revue NC'!$H$2:$H$47,$A10,'Revue NC'!$I$2:$I$47,B$3) -> 0 | C10: =COUNTIFS('Revue NC'!$H$2:$H$47,$A10,'Revue NC'!$I$2:$I$47,C$3) -> 1 | D10: =COUNTIFS('Revue NC'!$H$2:$H$47,$A10,'Revue NC'!$I$2:$I$47,D$3) -> 0 | E10: =SUM(B10:D10) -> 1 | F10: =COUNTIFS('Revue NC'!$H$2:$H$47,$A10,'Revue NC'!$O$2:$O$47,"<>") -> 0
A11: Imputation | B11: =COUNTIFS('Revue NC'!$H$2:$H$47,$A11,'Revue NC'!$I$2:$I$47,B$3) -> 1 | C11: =COUNTIFS('Revue NC'!$H$2:$H$47,$A11,'Revue NC'!$I$2:$I$47,C$3) -> 15 | D11: =COUNTIFS('Revue NC'!$H$2:$H$47,$A11,'Revue NC'!$I$2:$I$47,D$3) -> 0 | E11: =SUM(B11:D11) -> 16 | F11: =COUNTIFS('Revue NC'!$H$2:$H$47,$A11,'Revue NC'!$O$2:$O$47,"<>") -> 0
A12: Comptée à tort | B12: =COUNTIFS('Revue NC'!$H$2:$H$47,$A12,'Revue NC'!$I$2:$I$47,B$3) -> 3 | C12: =COUNTIFS('Revue NC'!$H$2:$H$47,$A12,'Revue NC'!$I$2:$I$47,C$3) -> 2 | D12: =COUNTIFS('Revue NC'!$H$2:$H$47,$A12,'Revue NC'!$I$2:$I$47,D$3) -> 0 | E12: =SUM(B12:D12) -> 5 | F12: =COUNTIFS('Revue NC'!$H$2:$H$47,$A12,'Revue NC'!$O$2:$O$47,"<>") -> 0
A13: Doublon | B13: =COUNTIFS('Revue NC'!$H$2:$H$47,$A13,'Revue NC'!$I$2:$I$47,B$3) -> 1 | C13: =COUNTIFS('Revue NC'!$H$2:$H$47,$A13,'Revue NC'!$I$2:$I$47,C$3) -> 0 | D13: =COUNTIFS('Revue NC'!$H$2:$H$47,$A13,'Revue NC'!$I$2:$I$47,D$3) -> 0 | E13: =SUM(B13:D13) -> 1 | F13: =COUNTIFS('Revue NC'!$H$2:$H$47,$A13,'Revue NC'!$O$2:$O$47,"<>") -> 0
A14: Total | B14: =SUM(B4:B13) -> 18 | C14: =SUM(C4:C13) -> 25 | D14: =SUM(D4:D13) -> 3 | E14: =SUM(E4:E13) -> 46 | F14: =SUM(F4:F13) -> 0
A16: Mesures (calculées sur le suivi et les NC SAP, septembre 2026)
A17: Lignes du suivi relues | B17: 475
A18: Motif cohérent avec le texte (lignes vérifiables : 437) | B18: 92 %
A19: Imputation cohérente avec la provenance écrite (216 lignes où elle est écrite) | B19: 94 %
A20: NC typées CABLES dans SAP (jan–juil, non supprimées) présentes dans le suivi | B20: 172 / 173 (la manquante : plaquettes)
A21: Lignes « coupé (trop) court » : court / coupé / abîmé | B21: 76 / 20 / 2
A22: Câbles couverts par les 475 lignes (estimation) | B22: ≈ 813
A23: Source : fichier « Suivi NCs – A30 – NC câbles et analyses », extraction SAP FTO2 (807 NC jan–juil) et fichier de défauts parsés (876 NC).

Sheet Revue NC
A1: NC | B1: Semaine | C1: Programme | D1: MSN | E1: Entité | F1: Motif (suivi) | G1: Imputation (suivi) | H1: Catégorie | I1: Niveau | J1: Ce que dit la NC | K1: Commentaire d'analyse (suivi) | L1: Proposition | M1: Remarque | N1: Réponse équipe | O1: Décision
A2: 216237277 | B2: S05 | C2: A350 | D2: 828 | E2: AIRBUS | F2: Câble non conforme | G2: Salle impression - opérateur | H2: Motif | I2: Erreur probable | J2: Sur la route 2S harnais 1101VB du MIP A350 nous avons constaté des câbles ADB24 trop courts. * ADB24 Longueur 50 MSN 0828 2792-0936 2792-0935 2792-0901 2792-0902 * Demandons la mise à disposition des câbles. -- -- -- -- -- -- -- -- -- -- -- -- -- -- -- -- -- -… | K2: 4 câble ADB24 trop court : 2792-0936 / 50 cm : 2792-0935 / 50 cm : 2792-0901 / 50cm : 2792-0902 / 50 cm | L2: Câble court | M2: NC aussi supprimée dans SAP
A3: 216481631 | B3: S08 | C3: A350 | D3: 829 | E3: ERMA | F3: Câble abimé | G3: Production ligne série | H3: Motif | I3: Erreur probable | J3: — | K3: câble suivant coupé trop court: 4612-0353 KL24 L: 419 cm | L3: Câble court | M3: Le commentaire dit « coupé trop court »
A4: 216487866 | B4: S08 | C4: A400M | D4: 160 | E4: AIRBUS | F4: Câble abimé | G4: Production ligne série | H4: Motif | I4: Erreur probable | J4: Câble trop court | K4: Câble coupé trop court: 2453-0607 DR24 L: 316 cm | L4: Câble court | M4: Le commentaire dit « coupé trop court »
A5: 216313639 | B5: S06 | C5: A330 | D5: 2152 | E5: AIRBUS | F5: Câble coupé | G5: Production ligne série | H5: Motif | I5: Erreur probable | J5: sur la ligne A330 , nous constatons que le cable 2452-0017 Longueur:300 Type : DR Jauge:24 Cause : Inversion câble trop court -- -- -- -- -- -- -- -- -- -- -- -- -- -- -- -- -- -- -- -- -- -- -- -- -- -- -- -- -- -- -- -- -- -- -- -- -- -- -- -- -- -- -- -- --… | K5: 1 câble DR24 / 2452-0017 cable trop court suite a erreur de cheminement | L5: Câble court | M5: « trop court suite à erreur de cheminement » : aucun câble coupé
A6: 216773861 | B6: S12 | C6: A330 | D6: 2151 | E6: AIRBUS | F6: Câble coupé | G6: Production ligne série | H6: Motif | I6: Erreur probable | J6: Lors du test du meuble 740VU MSN 2151 , il a été constaté un câble trop court suite à erreur de cheminement. * Câble 2823-0001 type DR 20 , longueur 220cm * Merci de refabriquer ce câble. -- -- -- -- -- -- -- -- -- -- -- -- -- -- -- -- -- -- -- -- -- -- -- -- … | K6: Câble 2823-0001 type DR 20, longueur 220cm mauvais cheminement opérateur | L6: Câble court | M6: « trop court suite à erreur de cheminement »
A7: 218193868 | B7: S37 | C7: A330 | D7: 2170 | E7: AIRBUS | F7: Câble coupé | G7: Production ligne série | H7: Motif | I7: Erreur probable | J7: Sur la ligne A330 , MSN 2170 , poste shunt 740 VU , nous constatons que le câble suivant est trop court suite à une erreur de cheminement : * - 2425-0010 - DR24 - LONGUEUR 165 CM * Nous demandons la re fabrication du câble. | K7: - 2425-0010 - DR24 - LONGUEUR 165 CM trop court suite à une erreur de cheminement: | L7: Câble court | M7: « trop court suite à une erreur de cheminement »
A8: 217356474 | B8: S22 | C8: A350 | D8: 856 | E8: ERMA | F8: Câble coupé | G8: Production ligne série | H8: Motif | I8: Erreur probable | J8: — | K8: Câble endommagé. 3245-0069 AD24 | L8: Câble abimé | M8: Le commentaire dit « Câble endommagé »
A9: 217716852 | B9: S27 | C9: A350 | D9: 859 | E9: ERMA | F9: Câble non conforme | G9: Production ligne série | H9: Motif | I9: Erreur probable | J9: — | K9: 2792-0348 DR18 L85cm a été endommagé. | L9: Câble abimé | M9: « a été endommagé »
A10: 217544334 | B10: S24 | C10: A350 | D10: 860 | E10: ERMA | F10: Câble court | G10: Salle impression - Machine | H10: Motif | I10: Erreur probable | J10: — | K10: Câble manquant dr24 7325-0087 | L10: Câble manquant | M10: Le commentaire dit « Câble manquant »
A11: 217796503 | B11: S28 | C11: A400M | D11: 165 | E11: AIRBUS | F11: Câble coupé | G11: Production ligne série | H11: Motif | I11: Erreur probable | J11: — | K11: Câble DR24 2453-0932 et 3 manchons 2826 0052, 2826 0104 et 2826 0055 suite perte de l'opérateur, un câble et 3 manchons sont manquants. | L11: Câble manquant | M11: Câble et 3 manchons perdus par l’opérateur
A12: 217899785 | B12: S30 | C12: A330 | D12: 2169 | E12: AIRBUS | F12: Câble court | G12: Salle impression - Machine | H12: Motif | I12: Erreur probable | J12: Sur la ligne A330 , MSN 2169 , 742 VU , nous constatons sur le circuit de surveillance que les câbles suivants sont manquants : * - 2453-0794 - Type : DK246 - Longueur : 85 * - 2453-0865 - Type : DK246 - Longueur : 75 * Nous demandons la fabrication des câbles… | K12: - 2453-0794 - Type : DK246 - Longueur : 85 - 2453-0865 - Type : DK246 - Longueur : 75 | L12: Câble manquant | M12: La NC dit « les câbles suivants sont manquants » ; le commentaire ne recopie que la liste
A13: 216958965 | B13: S15 | C13: A350 | D13: 839 | E13: AIRBUS | F13: Câble non conforme | G13: Définition ME | H13: Hors périmètre câble | I13: Erreur probable | J13: Problème localisé au poste intégration : Les plaquettes de ref E0248A2-6H9 et de FIN 7DG2 A , 8DG2 A , 7DG1 A , 8DG1 A reçues ne sont pas conformes ( FIN centré sur plaquette ) . Merci de refabriquer ( en nombre suffisant ) ces quatre FIN de plaquettes avec le… | K13: Les plaquettes de ref E0248A2-6H9 et de FIN 7DG2 A, 8DG2 A, 7DG1 A, 8DG1 A reçues ne sont pas conformes(FIN centré sur plaquette). | L13: Plaquette (hors motifs câble) | M13: Produit = Plaquette mais motif « Câble non conforme »
... A23: 216866658 | B23: S14 | C23: A330 | D23: 2154 | E23: AIRBUS | F23: Câble manquant | G23: Production ligne série | H23: Plusieurs défauts, un seul motif | I23: À confirmer | J23: Sur la ligne A330 , nous constatons que les câbles sont manquants : DR 16 : 2467-0024 long 265 DR 16 : 2467-0038 long 260 DR 12 : 4961-0047 long 211 DR 10 : 2434-0044 long 75 câble trop court : DR 10 : 2434-0043 long 75 -- -- -- -- -- -- -- -- -- -- -- -- -- -… | K23: Manquant DR 16: 2467-0024 long 265 / DR 16 : 2467-0038 long 260 / DR 12: 4961-0047 long 211 / DR 10: 2434-0044 long 75 / câble trop court: DR 10: 2434-0043 long 75 ensemble des câbles mal cheminés Après enquete par NG: câble retrouvé mais mis dans un mauvais bac au niveau du kitting | L23: Scinder : 4 manquants + 1 court | M23: Le câble court disparaît des statistiques
A24: 217339657 | B24: S21 | C24: A350 | D24: 851 | E24: AIRBUS | F24: Câble court | G24: Production ligne série | H24: Plusieurs défauts, un seul motif | I24: À confirmer | J24: Sur la ligne A350 , poste sous-ensemble , route 2M , nous avons constaté que deux cables sont non conformes. * Il s'agit du cable AD20 / 3119-0348 d'une longueur de 220cm qui est endommagé. Et du cable DR20 / 2751-0039 d'une longueur de 150cm qui à été coupé t… | K24: DR20 / 2751-0039 d'une longueur de 150cm / AD20 / 3119-0348 d'une longueur de 220cm | L24: Scinder : 1 abîmé + 1 coupé trop court
A25: 217989585 | B25: S33 | C25: A350 | D25: 869 | E25: ERMA | F25: Câble abimé | G25: Salle impression - Machine | H25: Plusieurs défauts, une seule imputation | I25: À confirmer | J25: — | K25: 2792-0767 AD24 Long:680 cm (reçu coupé en 2 ); 5251-0036 MLA18 Long:652 cm ( abimé à la meo ) enquete: AD24 coupé par la scotcheuse de la rapidshare | L25: Scinder : 1 reçu coupé (machine) + 1 abîmé à la MEO (production)
A26: 216045553 | B26: S02 | C26: A350 | D26: 818 | E26: ERMA | F26: Câble court | G26: Production ligne série | H26: Imputation | I26: À confirmer | J26: — | K26: Motif : Lors de l'application de l'OF 1027399380 nous constatons que le câble suivant a été reçu trop court 4411-0298 WX26 L:707cm | L26: Salle impression, sauf si l’analyse a montré une coupe en ligne | M26: Le texte dit « reçu » ; imputé à la production
A27: 216104852 | B27: S03 | C27: A350 | D27: 824 | E27: ERMA | F27: Câble abimé | G27: Production ligne série | H27: Imputation | I27: À confirmer | J27: — | K27: câble suivant a été reçu abimé: 3242-0411 AD24 L:632 cm | L27: Salle impression, sauf si l’analyse a montré une coupe en ligne | M27: Le texte dit « reçu » ; imputé à la production
A28: 216456970 | B28: S08 | C28: A350 | D28: 829 | E28: ERMA | F28: Câble court | G28: Production ligne série | H28: Imputation | I28: À confirmer | J28: — | K28: câble suivant a été reçu trop court en TA: 3314-0323 AD24 L: 582 cm | L28: Salle impression, sauf si l’analyse a montré une coupe en ligne | M28: Le texte dit « reçu » ; imputé à la production
A29: 216564123 | B29: S09 | C29: A350 | D29: 835 | E29: ERMA | F29: Câble court | G29: Production ligne série | H29: Imputation | I29: À confirmer | J29: — | K29: câble suivant a été reçu trop court: 4612-0571 VNB22 L: 265 cm | L29: Salle impression, sauf si l’analyse a montré une coupe en ligne | M29: Le texte dit « reçu » ; imputé à la production
A30: 216816792 | B30: S13 | C30: A350 | D30: 843 | E30: ERMA | F30: Câble court | G30: Production ligne série | H30: Imputation | I30: À confirmer | J30: — | K30: câble suivant a été reçu trop court: 4612-1146 DR22 L: 290 cm Fichier LAS OK | L30: Salle impression, sauf si l’analyse a montré une coupe en ligne | M30: Le texte dit « reçu » ; imputé à la production
A31: 216835808 | B31: S13 | C31: A350 | D31: 837 | E31: ERMA | F31: Câble court | G31: Production ligne série | H31: Imputation | I31: À confirmer | J31: — | K31: câble suivant a été reçu trop court: 3313-0245 ADB24 L: 524 cm | L31: Salle impression, sauf si l’analyse a montré une coupe en ligne | M31: Le texte dit « reçu » ; imputé à la production
A32: 216879671 | B32: S14 | C32: A350 | D32: 843 | E32: ERMA | F32: Câble court | G32: Production ligne série | H32: Imputation | I32: À confirmer | J32: — | K32: câble suivant a été reçu trop court: 2792-0025 ADB24 Long:615 cm | L32: Salle impression, sauf si l’analyse a montré une coupe en ligne | M32: Le texte dit « reçu » ; imputé à la production
A33: 218143176 | B33: S36 | C33: A350 | D33: 873 | E33: ERMA | F33: Câble court | G33: Production ligne série | H33: Imputation | I33: À confirmer | J33: — | K33: AD24 4612-0101 / Reçu trop court | L33: Salle impression, sauf si l’analyse a montré une coupe en ligne | M33: Le texte dit « reçu » ; imputé à la production
A34: 218143463 | B34: S36 | C34: A350 | D34: 872 | E34: AIRBUS | F34: Câble court | G34: Production ligne série | H34: Imputation | I34: À confirmer | J34: — | K34: Câble en sous-longueur. / Reçu trop court | L34: Salle impression, sauf si l’analyse a montré une coupe en ligne | M34: Le texte dit « reçu » ; imputé à la production
A35: 216251878 | B35: S05 | C35: A350 | D35: 5106 | E35: AIRBUS | F35: Câble court | G35: Production ligne série | H35: Imputation | I35: À confirmer | J35: Sur MDCD A350 MSN5106 nous avons receptionné des câbles trop courts. * Qté:6 * Référence : 3336-5019/MLB18/155CM 3336-5049/MLB18/155CM 3336-5050/MLB18/155CM 3336-5051/MLB18/155CM 3336-5052/MLB18/155CM 3336-5053/MLB18/155CM * Demandons le remplacement des câble… | K35: 6 MLB18 court production, | L35: Trancher : NC « réceptionné trop courts » vs analyse « court production »
A36: 216506719 | B36: S08 | C36: A350 | D36: 834 | E36: AIRBUS | F36: Câble court | G36: Production ligne série | H36: Imputation | I36: À confirmer | J36: De : MONTANA , VIRGINIE Action : Créer Date : 2026-02-20 12:51:32 Commentaire : Il y a 3 câbles trop courts venant de l'impression sur le MSN 834 AD22 alu 3422-0438 LONG 460 CM AD22 alu 3422-0437 LONG 460 CM DR24 cuivre 3422-0436 LONG 460 CM * demandons le rem… | K36: 3 câbles courts production | L36: Trancher : NC « venant de l’impression » vs analyse « courts production »
A37: 217398603 | B37: S22 | C37: A350 | D37: 856 | E37: ERMA | F37: Câble court | G37: Salle impression - opérateur | H37: Imputation | I37: Erreur probable | J37: — | K37: 1 AD24 2792-0520 trop court production* | L37: Production ligne série | M37: Le commentaire dit lui-même « trop court production »
A38: 218244963 | B38: S37 | C38: A350 | D38: 876 | E38: ERMA | F38: Câble court | G38: Salle impression - opérateur | H38: Imputation | I38: À confirmer | J38: — | K38: 2351-3375 KL24 L275cm est en sous-longueur suite à la remise en conformité du sertissage. | L38: Production ligne série, sauf si l’opération est faite en salle | M38: Cause en ligne (sertissage, cheminement, MEO) imputée à la salle ; même analyste, S37–S40
A39: 218359357 | B39: S38 | C39: A350 | D39: 876 | E39: ERMA | F39: Câble abimé | G39: Salle impression - opérateur | H39: Imputation | I39: À confirmer | J39: — | K39: 2724-0118 ADB24 L702cm a été endommagé lors du cheminement. | L39: Production ligne série, sauf si l’opération est faite en salle | M39: Cause en ligne (sertissage, cheminement, MEO) imputée à la salle ; même analyste, S37–S40
A40: 218374736 | B40: S38 | C40: A350 | D40: 873 | E40: AIRBUS | F40: Câble abimé | G40: Salle impression - opérateur | H40: Imputation | I40: À confirmer | J40: — | K40: 2351-2961 ADB24 ABIMER AU SERTISSAGE | L40: Production ligne série, sauf si l’opération est faite en salle | M40: Cause en ligne (sertissage, cheminement, MEO) imputée à la salle ; même analyste, S37–S40
A41: 218403302 | B41: S40 | C41: A350 | D41: 877 | E41: ERMA | F41: Câble abimé | G41: Salle impression - opérateur | H41: Imputation | I41: À confirmer | J41: — | K41: 2799-0008 VNA24 L549cm abîmé suite à une mauvaise mise en oeuvre de l'AUTO-SOUDEUR | L41: Production ligne série, sauf si l’opération est faite en salle | M41: Cause en ligne (sertissage, cheminement, MEO) imputée à la salle ; même analyste, S37–S40
A42: 216632291 | B42: S10 | C42: A350 | D42: 836 | E42: ERMA | F42: Câble manquant | G42: Production ligne série | H42: Comptée à tort | I42: Erreur probable | J42: — | K42: câble suivant est manquant: 4612-0219 DR24 L: 150 cm Fichier LAS OK | L42: Retirer des statistiques | M42: Action : « ANNULER TCLO CAR DOUBLON »
A43: 216679350 | B43: S11 | C43: A350 | D43: 840 | E43: AIRBUS | F43: Câble court | G43: Production ligne série | H43: Comptée à tort | I43: Erreur probable | J43: Sur le poste sous ensemble 2S des câbles ont été coupés trop courts , veuillez s'il vous plait proceder a leur remplacement. * 2792-0822 : ADB 24 , 172 cm 2792-0897 : ADB 24 , 172 cm 2792-0827 : ADB 24 , 172 cm 2792-0828 : ADB 24 , 316 cm 2792-0900 : ADB 24 , … | K43: 6 ADB24 coupé court lors de la mise en oeuvre par l'opératrice | L43: Retirer des statistiques | M43: Action : « TCLO les câbles sont OK » ; supprimée dans SAP
A44: 217766863 | B44: S28 | C44: A350 | D44: 864 | E44: AIRBUS | F44: Câble manquant | G44: Production ligne série | H44: Comptée à tort | I44: Erreur probable | J44: 2 Cables DR24 manquants | K44: 2 DR24 3313-0187 et 4612-0218 manquant et retrouver dans la poubelle TCLOS NC + S03 | L44: Retirer des statistiques | M44: Câbles « retrouvés dans la poubelle, TCLOS NC » ; supprimée dans SAP
A45: 216280851 | B45: S05 | C45: A350 | D45: 829 | E45: AIRBUS | F45: Câble abimé | G45: Production ligne série | H45: Comptée à tort | I45: À confirmer | J45: Sur la ligne A350 , sous-ensemble route 2S du MSN 829 , nous avons constaté que le cable ADB24 / 2792-0905 d'une longueur de 590cm est abimé. Nous demandons le remplacement du cable et la remise en conformité du produit. -- -- -- -- -- -- -- -- -- -- -- -- -- … | K45: cable ADB24 / 2792-0905 d'une longueur de 590cm est abimé. | L45: Vérifier | M45: Supprimée dans SAP
A46: 217542504 | B46: S24 | C46: A350 | D46: 855 | E46: AIRBUS | F46: Câble court | G46: Production ligne série | H46: Comptée à tort | I46: À confirmer | J46: Sur la ligne A350 poste intégration nous avons constaté que le cable DR24 / 2797-1117 d'une longueur de 700cm a été mal cheminer et est par conséquent trop court. Nous demandons le remplacement du cable et la remise en conformité du produit -- -- -- -- -- -- -… | K46: DR24 / 2797-1117 d'une longueur de 700cm a été mal cheminer et par conséquent trop court. | L46: Vérifier | M46: Supprimée dans SAP
A47: 217517473 | B47: S24 | C47: A330 | D47: 2164 | E47: AIRBUS | F47: Câble abimé | G47: Production ligne série | H47: Doublon | I47: Erreur probable | J47: Sur la ligne A330 , 740 VU , MSN 2164 , nous constatons que le câble suivant est abîmé : * - N° 2425-0087 - Type : DR 22 - Longueur : 130 CM * Nous demandons la re fabrication du câble. -- -- -- -- -- -- -- -- -- -- -- -- -- -- -- -- -- -- -- -- -- -- -- -- --… | K47: N° 2425-0087 - Type: DR 22 - Longueur : 130 CM | L47: Garder une seule ligne | M47: NC présente deux fois dans le suivi

Sheet Convention coupé court
A1: Le texte dit « coupé (trop) court » dans 98 lignes : 76 classées « Câble court », 20 « Câble coupé », 2 « Câble abîmé ». Proposition : « Câble court » pour toute longueur insuffisante, « Câble coupé » seulement pour un câble sectionné.
A3: NC | B3: Semaine | C3: Programme | D3: Motif (suivi) | E3: Imputation (suivi) | F3: Commentaire d'analyse
A4: 216481631 | B4: S08 | C4: A350 | D4: Câble abimé | E4: Production ligne série | F4: câble suivant coupé trop court: 4612-0353 KL24 L: 419 cm
A5: 216487866 | B5: S08 | C5: A400M | D5: Câble abimé | E5: Production ligne série | F5: Câble coupé trop court: 2453-0607 DR24 L: 316 cm
A6: 216258704 | B6: S05 | C6: A350 | D6: Câble coupé | E6: Production ligne série | F6: 2 câbles coupé court par la production
A7: 216472727 | B7: S08 | C7: A400M | D7: Câble coupé | E7: Production ligne série | F7: Câble 3162-0047 DR22 L-398cm coupé trop court par operateur
A8: 216598114 | B8: S10 | C8: A400M | D8: Câble coupé | E8: Production ligne série | F8: Câbles AD22 4212-0810 coupé court par la production/longueur 585 cm.
A9: 216643933 | B9: S11 | C9: A330 | D9: Câble coupé | E9: Production ligne série | F9: Erreur de cheminement et câbles coupés court. Attention câbles déclarés en manquant
A10: 216718458 | B10: S11 | C10: A400M | D10: Câble coupé | E10: Production ligne série | F10: Les câbles coupés trop court par l'opérateur:DR 24-2122-0005 et 2122-0006 L:110,DR20-3042-00047 L:185,MLA18-4631-0004 L:200 etMLA22-4661-0003 L:200
A11: 216805558 | B11: S13 | C11: A350 | D11: Câble coupé | E11: Production ligne série | F11: 1 ADB20 coupé court par la production
A12: 216837425 | B12: S13 | C12: A400M | D12: Câble coupé | E12: Production ligne série | F12: Les câbles coupés trop court par l'opérateur:VNA24-3163-0301,3163-0302,3163-0263,3163-0261,3163-0251,3163-0253 / VNB24-3163-0974 / MLB24 -3163-0651; 3162-0134,3162-0135,3163-0650 / DR24 -3163-0271,3163-0311 et 3163-0269
A13: 216977496 | B13: S15 | C13: A350 | D13: Câble coupé | E13: Production ligne série | F13: 1 DR24 3161-0668 coupé trop court par la production
A14: 217016584 | B14: S16 | C14: A330 | D14: Câble coupé | E14: Production ligne série | F14: Câble 2453-2124 - Type : DR246 - Longueur : 60 CM coupé trop court
... A101: 218353119 | B101: S38 | C101: A350 | D101: Câble court | E101: Salle impression - Machine | F101: câble suivant coupé trop court: 2781-0012 MMG24 L: 266 cm

Sheet Absentes du suivi
A1: Reprises de câbles présentes dans SAP (périmètre FTO2) mais absentes du suivi. Les « listes de retouches test » regroupent plusieurs défauts dans une seule NC ; seule la ligne câble est citée.
A3: NC | B3: Type | C3: Date | D3: Programme | E3: Titre SAP | F3: Statut SAP | G3: Défaut(s) câble dans la NC | H3: Nb lignes câble
A4: 217447449 | B4: NC câble isolée | C4: 2026-06-03 | D4: A330 | E4: CABLE COURT SUITE ERREUR SERTISSAGE | F4: closed | G4: * Sur la ligne A330 , MSN 2161 , 538VU , nous constatons suite à une erreur de sertissage que le câble 4631-1221 est trop court. * Nous demandons la re fabrication du câb | H4: 1
A5: 218012174 | B5: NC câble isolée | C5: (après le 6 juillet) | F5: (inconnu) | G5: * Au poste intégration , route 2S , nous avons constaté que deux câbles ont été coupés trop courts. ( MEO longueur auto-soudeurs ) Merci de re-fabriquer les deux câbles s | H5: 1
A6: 217406743 | B6: NC plaquettes (à décider) | C6: 2026-05-29 | D6: A350 | E6: Plaquettes 100VN220 à réimprimer | F6: closed | G6: * Au poste sous-ensemble route 2S B , les plaquettes CDVE livrées 100VN220 ne sont pas conformes ( il manque `` BC2 ) . Merci de re-fabriquer des plaquettes CDVE au forma | H6: 1
A7: 216074163 | B7: Liste de retouches test | C7: 2026-01-08 | D7: A330 | E7: 2148 | F7: closed | G7: Câble BF24 N° : 2351-0459 manquant entre 19RN 1 ET 18RN 2. | Câble BF24 N° : 2351-0458 manquant entre 19RN 2 ET 18RN 1. Merci de remettre le VU en conformité. | H7: 2
A8: 216111281 | B8: Liste de retouches test | C8: 2026-01-13 | D8: A330 | E8: Retouche Test 612VU MSN 02148 | F8: closed | G8: Câble BF 24 N° : 2351-0303 manquant entre 15RN 1 et 16RN 2. | Câble BF 24 N° : 2351-0302 manquant entre 15RN 2 et 16RN 1. Merci de remettre le VU en conformité. | H8: 2
A9: 216195310 | B9: Liste de retouches test | C9: 2026-01-21 | D9: A330 | E9: Retouche Test 313VU MSN 02145. | F9: closed | G9: 4 Câbles manquants en 261VT 1 : - Câble BF24 N°:3163-0918 manquant entre 261VT 1 A et 54FP1 A B1. - Câble BF24 N°:3163-0919 manquant entre 261VT 1 B et 54FP1 A A1. - Câbl | H9: 1
A10: 216195654 | B10: Liste de retouches test | C10: 2026-01-21 | D10: A330 | E10: Retouche Test 31'VU MSN 02145. | F10: closed | G10: 3 Câbles manquants en 260VT 1 : - Câble BF 24 N° : 3163-0924 Manquant entre 260VT 1 A et 54FP2 A B1. - Câble BF 24 N° : 3163-0925 Manquant entre 260VT 1 B et 54FP2 A A1. | Shunt BF24 N° : 3448-0056 Manquant sur 4WZ2 A entre les bornes 5 et 9. | Shunt BF24 N° : 3163-0923 Manquant sur 54FP2 A entre les bornes A3 et 4. Merci de remettre le VU en conformité. | H10: 3
A11: 217055268 | B11: Liste de retouches test | C11: 2026-04-17 | D11: A330 | E11: Retouche Test 616VU MSN 02157. | F11: closed | G11: Câble BF24 N° : 2351-0458 Manquant entre 18RN 1 et 19RN 2. | Câble BF24 N° : 2351-0459 Manquant entre 18RN 2 et 19RN 1. Câbles Non imprimés. Merci de remettre le VU en conformité. | H11: 2
A12: 216321686 | B12: Liste de retouches test | C12: 2026-02-03 | D12: A350 | E12: QUADRAX ABIME | F12: closed | G12: CABLE QUADRAX DU FIN 1WK11A BORNE HH AU FIN 1608VC095A ENDOMMAGE A COMMANDER ( URGENT ) . | H12: 1
A13: 216579161 | B13: Liste de retouches test | C13: 2026-02-27 | D13: A350 | E13: RETOUCHE TEST MSN 846 CABLE ABIME | F13: closed | G13: 10FC2A CABLE 3422-0293 ABIME A CHANGER. | H13: 1
A14: 217054293 | B14: Liste de retouches test | C14: 2026-04-17 | D14: A350 | E14: CABLE ENDOMMAGE MSN0839. | F14: closed | G14: 500VT202 MODULE 2 BORNE X CABLE ENDOMMAGE. | H14: 1
A15: 217123040 | B15: Liste de retouches test | C15: 2026-04-24 | D15: A350 | E15: CABLE ENDOMMAGE MSN0843. | F15: closed | G15: CABLE ENDOMMAGE 300VT101 7U AU NIVEAU DE LA FERRULE. | H15: 1
A16: 217371996 | B16: Liste de retouches test | C16: 2026-05-26 | D16: A350 | E16: CABLE COUPE | F16: closed | G16: CABLE COUPE ENTRE 1608VC062A BORNE 19 ET 100VT400 5D. | H16: 1
A17: 217811190 | B17: Liste de retouches test | C17: (après le 6 juillet) | F17: (inconnu) | G17: 2WTA BORNE A , CABLE ENDOMMAGE AU NIVEU DE LA FERRULE. | H17: 1
A18: 218056821 | B18: Liste de retouches test | C18: (après le 6 juillet) | F18: (inconnu) | G18: CABLE ENDOMMAGE ENTRE 1WK53A BORNE 6A ET 300VT200 1T.CABLE N°3161-0860. | H18: 1
A19: 218159740 | B19: Liste de retouches test | C19: (après le 6 juillet) | F19: (inconnu) | G19: Shunt AD24 N° : 2351-3421 manquant entre 3RN1 A borne N et 3RN1 A borne FF. | H19: 1

Sheet Causes nommées
A1: Lignes où le commentaire d’analyse (ou la NC) nomme une cause au-delà de l’état du câble. Le motif actuel n’enregistre que l’état (court, abîmé…), donc ces causes ne sont pas comptables aujourd’hui.
A3: Cause nommée | B3: NC | C3: Semaine | D3: Motif (suivi) | E3: Imputation (suivi) | F3: Commentaire d'analyse
A4: Coupe sur table (trait de coupe) | B4: 216805983 | C4: S13 | D4: Câble court | E4: Production ligne série | F4: 10 câbles coupé court cause mauvais cheminement opérateur sur table
A5: Coupe sur table (trait de coupe) | B5: 216826753 | C5: S13 | D5: Câble court | E5: Production ligne série | F5: 4 câbles coupé au mauvais trait de coupe sur table
A6: Coupe sur table (trait de coupe) | B6: 217501773 | C6: S24 | D6: Câble court | E6: Production ligne série | F6: - 2452-0063 Type DR10 Longueur 50 CM - 2452-0064 Type DR10 Longueur 50 CM SUITE ERREUR DE COUPE
A7: Coupe sur table (trait de coupe) | B7: 217838827 (vide dans le suivi) | D7: Câble court | E7: Production ligne série | F7: Lors du sertissage des têtes B du harnais 4715VB MSN 13697, PB10093, la coupe des câbles à été réalisée trop courte (erreur entre trait de coupe et longueur théorique)
A8: Câble perdu / jeté en ligne | B8: 217103724 | C8: S17 | D8: Câble manquant | E8: Production ligne série | F8: 1 câble reprise manquant DR24 3313-0187 (perdu par la prod)
A9: Câble perdu / jeté en ligne | B9: 217108805 | C9: S17 | D9: Câble manquant | E9: Production ligne série | F9: 9 câbles AD24/AD22 Manquant car les opérateurs les ont jettés à la poubelle
A10: Câble perdu / jeté en ligne | B10: 217174106 | C10: S18 | D10: Câble manquant | E10: Production ligne série | F10: 1 câble reprise DR24 3313-0185 perdu par la production
A11: Câble perdu / jeté en ligne | B11: 217283624 | C11: S20 | D11: Câble manquant | E11: Production ligne série | F11: 1 câble DR24 3313-0187 jeté à la poubelle
A12: Câble perdu / jeté en ligne | B12: 217376442 | C12: S22 | D12: Câble manquant | E12: Production ligne série | F12: 2 DR24 3161-0671/3161-0670 perdu par la porduction
A13: Câble perdu / jeté en ligne | B13: 217766863 | C13: S28 | D13: Câble manquant | E13: Production ligne série | F13: 2 DR24 3313-0187 et 4612-0218 manquant et retrouver dans la poubelle TCLOS NC + S03
A14: Câble perdu / jeté en ligne | B14: 217796503 | C14: S28 | D14: Câble coupé | E14: Production ligne série | F14: Câble DR24 2453-0932 et 3 manchons 2826 0052, 2826 0104 et 2826 0055 suite perte de l'opérateur, un câble et 3 manchons sont manquants.
A15: Câble perdu / jeté en ligne | B15: 218161820 | C15: S36 | D15: Câble manquant | E15: Production ligne série | F15: 1 DR18 Manquant perdu
A16: Câble perdu / jeté en ligne | B16: 218256506 | C16: S37 | D16: Câble manquant | E16: Salle impression - Machine | F16: 1 câble AD22 3313-0089 manquant au tête A (perdu impression)
A17: Câble perdu / jeté en ligne | B17: 218391202 | C17: S39 | D17: Câble manquant | E17: Salle impression - opérateur | F17: 1 câble manquant au tête A perdu AD24 3251-0094
A18: Erreur de cheminement | B18: 216117298 | C18: S03 | D18: Câble court | E18: Production ligne série | F18: Câble 3161-0076 DR 24 L165cm trop court suite à un mauvais cheminement.
A19: Erreur de cheminement | B19: 216252882 | C19: S05 | D19: Câble court | E19: Production ligne série | F19: Suite à un mauvais cheminement le câble DR20 2824-0069 Longueur 270cm est trop court.
... A36: Erreur de cheminement | B36: 217300652 | C36: S21 | D36: Câble court | E36: Production ligne série | F36: DK24 longueur 200 2424-0053 est trop court. Circe et Elec ABC OK Du à mauvais cheminement
A37: Erreur de cheminement | B37: 217310574 | C37: S21 | D37: Câble coupé | E37: Production ligne série
A38: Erreur de cheminement | B38: 217317069 | C38: S21 | D38: Câble court | E38: Production ligne série
A39: Erreur de cheminement | B39: 217420085 | C39: S23 | D39: Câble court | E39: Production ligne série | F39: N° Câble : 3154-0628- Type: DK24 - Longueur: 160CM
A40: Erreur de cheminement | B40: 217434411 | C40: S23 | D40: Câble court | E40: Salle impression - Machine | F40: CABLE ADB24 BIFILAIRE TROP COURT 2792-0076
A41: Erreur de cheminement | B41: 217445085 | C41: S23 | D41: Câble court | E41: Production ligne série | F41: 1 MLB24 2285-0001 mauvais cheminement opérateur
A42: Erreur de cheminement | B42: 217474320 | C42: S23 | D42: Câble court | E42: Production ligne série | F42: câble 2453-2203B DK 246 est trop court.
A43: Erreur de cheminement | B43: 217542504 | C43: S24 | D43: Câble court | E43: Production ligne série | F43: DR24 / 2797-1117 d'une longueur de 700cm a été mal cheminer et par conséquent trop court.
A44: Erreur de cheminement | B44: 217542655 | C44: S24 | D44: Câble court | E44: Production ligne série | F44: Câble 2797-0600 a été mal cheminé
A45: Erreur de cheminement | B45: 217584201 | C45: S25
A46: Erreur de cheminement | B46: 217789224 | C46: S28 | D46: Câble court | E46: Production ligne série | F46: 1 ADB24 2792-0540 trop court mauvais cheminement opérateur
A47: Erreur de cheminement | B47: 218044166 | C47: S34 | D47: Câble abimé | E47: Production ligne série | F47: Le câble a été endommagé lors du cheminement. 3245-0069 AD24 L675cm
A48: Erreur de cheminement | B48: 218193059 | C48: S37 | D48: Câble abimé | E48: Production ligne série | F48: 1 AD24 2797-0651 Abîmé
A49: Erreur de cheminement | B49: 218193868 | C49: S37 | D49: Câble coupé | E49: Production ligne série | F49: - 2425-0010 - DR24 - LONGUEUR 165 CM trop court suite à une erreur de cheminement:
A50: Erreur de cheminement | B50: 218208025 | C50: S37 | D50: Câble court | E50: Production ligne série | F50: Mauvais cheminement câble court opérateur pord
A51: Erreur de cheminement | B51: 218230122 | C51: S37 | D51: Câble court | E51: Production ligne série | F51: Câble AD24 mal cheminé ET coupé court
A52: Erreur de cheminement | B52: 218359357 | C52: S38 | D52: Câble abimé | E52: Salle impression - opérateur | F52: 2724-0118 ADB24 L702cm a été endommagé lors du cheminement.
A53: Machine RapidShare (coupe au scotchage, fin de bobine) | B53: 217941639 | C53: S30 | D53: Câble court | E53: Salle impression - Machine | F53: 2792-0538 AD24 - Court (ANALYSE ST : La machine coupe les câbles suite a une agmentation d'isolant)
A54: Machine RapidShare (coupe au scotchage, fin de bobine) | B54: 217942079 | C54: S30 | D54: Câble court | E54: Salle impression - Machine | F54: Court (ANALYSE ST : La machine coupe les câbles suite a une agmentation d'isolant) 3 AD24
A55: Machine RapidShare (coupe au scotchage, fin de bobine) | B55: 217982664 | C55: S33 | D55: Câble court | E55: Salle impression - Machine | F55: Court AD 24 numero : 3251- 0078 pour une longueur de 620cm (enquete: la rapidshare coupe de temps en temps un morceau de cable lors de la phase de scotchage)
A56: Machine RapidShare (coupe au scotchage, fin de bobine) | B56: 217989585 | C56: S33 | D56: Câble abimé | E56: Salle impression - Machine | F56: 2792-0767 AD24 Long:680 cm (reçu coupé en 2 ); 5251-0036 MLA18 Long:652 cm ( abimé à la meo ) enquete: AD24 coupé par la scotcheuse de la rapidshare
A57: Machine RapidShare (coupe au scotchage, fin de bobine) | B57: 218145092 | C57: S36 | D57: Câble abimé | E57: Salle impression - Machine | F57: 1 AD24 3314-0231 abîmé par rapidshare (machine)
...

Sheet Hygiène du suivi
A1: Point | B1: NC | C1: Constat
A2: Doublon | B2: 217517473 | C2: NC présente sur deux lignes (même contenu).
A3: N° de NC vide | B3: → 217838827 | C3: Ligne « harnais 4715VB MSN 13697 » sans n° de NC ; la NC SAP correspondante est 217838827.
A4: N° de NC erroné | B4: 216931839 | C4: Le n° pointe vers une NC rampe (protection alodine), supprimée dans SAP ; le commentaire décrit un câble coupé court.
A5: Date de création | B5: 216293872, 216294895 | C5: Année 2029 au lieu de 2026.
A6: Date de création | B6: 217992504 | C6: Date mal formée : « 1208/2026 ».
A7: Date OF | B7: 216053747 | C7: OF daté du 06/01/2025, NC du 06/01/2026 (année).
A8: NC supprimées dans SAP | B8: 216237277, 216280851, 216679350, 216931839, 217542504, 217766863 | C8: Toujours comptées dans le suivi.
A9: NC annulées (TCLO) | B9: 216632291, 216679350, 217766863 | C9: La colonne Action ou le commentaire dit TCLO / doublon / câbles OK / retrouvés à la poubelle ; toujours comptées.
A10: Responsable TSFS | B10: — | C10: « SAMIR », « Samir », « SAMIR » (avec espace) : une personne, trois graphies ; « NOUVEAU ST » utilisé comme nom.
A11: Commentaire TSFS | B11: — | C11: « Imprimé » écrit de 6 façons ; la colonne vaut « Imprimé » partout : elle ne porte pas d’information.
A12: Porteur d'action / Statut | B12: — | C12: Vides sur les 475 lignes ; « Action » renseignée 3 fois.
... A14: Provenance non écrite | B14: — | C14: 236 lignes dont le commentaire ne dit pas si le câble est arrivé ainsi ou a été abîmé en ligne ; 174 d’entre elles sont imputées à la production.
